Workbook

Sheet GUIDE
B2: HOW THIS MACHINE-PLANNING PACK WORKS
C3: Six visible tabs, in reading order: MD VIEW → DASHBOARD → LINE PLAN → MC MASTER → EMBELISHMENT → MC MAP. Backstage and hidden: DEMAND BY DATE (the daily engine), WORKINGS (helpers), plus PPC and MACHINE MASTER which are ARCHIVES ONLY — nothing reads them, and updating them changes nothing.
B5: QUICK START — 60 SECONDS
B6: 1. Type the plan | C6: On LINE PLAN, pick a style in each cell of the grid B6:DB31 (26 lines down, 105 dates across). Use the dropdown — it only offers styles that exist. The cell colours itself automatically; you never paint anything.
B7: 2. Watch the check cell | C7: LINE PLAN HA2 must read "ALL PLANNED STYLES CAN BE PRICED". If it turns red it tells you how many cells use a style with no machine recipe — those cells are NOT being costed. Fix before trusting any number.
B8: 3. Pick a date | C8: On DASHBOARD, use the yellow date picker to choose any day. Every number re-prices to that day. MD VIEW does the same at month level.
B9: 4. Read the KPIs | C9: Installed · Required · Utilisation · Groups short · Lines loaded · Output. If "Groups short" is above zero, the plan cannot physically be run that day even if total machines look sufficient.
B10: 5. Buy against the peak | C10: The PEAK MACHINE DEMAND block uses the worst day in the whole plan, not today. Purchase decisions use that table — never the single-day view.
B12: THE ONLY CELLS YOU EVER TYPE IN
B13: LINE PLAN B2 and B3 | C13: THE TWO DATE CONTROLS (yellow). B2 = plan start date. B3 = how many days the plan covers. Change B3 and the horizon extends or shrinks instantly — dates, the grid, the daily engine and both dashboards all follow. Capacity is built to 200 days; do not exceed that number. Month views cover the first four calendar months from the plan start.
B14: LINE PLAN B6:GS31 | C14: THE PLAN ITSELF. One style per line per date, chosen from the dropdown. Days beyond the horizon set in B3 are inert and cost nothing.
B15: LINE PLAN GY36:GY61 | C15: Which thermal style each line runs, when that line has THERMAL days. THERMAL on its own is a category, not a style, so it cannot be priced until you name the variant here.
B16: MC MASTER A3:C28 | C16: How many of each machine we own. This sheet IS our capacity. Machines are keyed by name, so changing a quantity is all that is needed.
B17: EMBELISHMENT | C17: The machine recipe per style — 25 operation rows × 42 style columns. Row 28 is the daily output target. This is the demand side of the model. Fully editable.
B18: MC MAP AG33:AG80 | C18: GARMENT TYPE per style, chosen from the dropdown. Cells reading "NEEDS INPUT" (shaded pink) are still blank.
B19: MC MAP AJ33:AJ43 | C19: THE GARMENT MASTER LIST. The only place garment names are typed. Add a new garment type here FIRST, then it becomes selectable in column AG.
B20: MC MAP K5:M28 / B5:B29 / B120 | C20: The alias table (planner's text → EMBELISHMENT column → category), the operation→machine map, and the month picker for the month view.
B21: DASHBOARD C4 / D4 / E4 / K71 | C21: View switch (DAY / MONTH END / MONTH PEAK), as-of date, month, and the garment picker for the drill-down. MD VIEW D4 is its month picker.
B22: DEMAND BY DATE BS | C22: Working-day calendar, Y or N per date. Days you add by raising B3 default to Y, except Sundays which default to N. Override any day by typing over it.
B23: EVERYTHING ELSE IS LOCKED | C23: Every sheet is now protected. The cells listed above are the only ones that accept typing — every formula in the pack is locked and Excel will refuse to overwrite it. There is no password, so the protection can be lifted from Review › Unprotect Sheet if a structural change is genuinely needed. Treat that as a deliberate act, not a workaround.
B24: Also blocked | C24: Sorting, filtering, and inserting or deleting rows and columns are switched off on every sheet. Sorting the plan grid used to scramble the row references behind it — that can no longer happen by accident.
B26: HOW THE DATA FLOWS
B27: The chain | C27: LINE PLAN typed styles → LINE PLAN resolved grid (expands THERMAL into the actual variant) → MC MAP block 3 pricing matrix (how many of each machine does this style need?) → DEMAND BY DATE (repeat that sum for every line, every day) → DASHBOARD / MD VIEW (compare against MC MASTER installed).
B28: In plain words | C28: Every line runs one style. Every style has a fixed machine recipe. So the machines needed on any day = the sum of 26 recipes. Subtract what we own, group by group, and the shortage or surplus falls out.
B29: Where to debug | C29: MC MAP is the workshop — all joining, translating and adding up happens there in the open where you can audit it. If a DASHBOARD number looks wrong the cause is in MC MAP or LINE PLAN, never on the DASHBOARD itself.
B31: MC MAP — THE WORKSHOP
B32: Block 1 (rows 4-28) | C32: OPERATION → MACHINE. A straight 1:1 join on the machine name, because MC MASTER names its machines exactly as EMBELISHMENT names its operation rows. Column C pulls the Available count from MC MASTER.
B33: Alias table (K5:M28) | C33: Planner's text → EMBELISHMENT recipe column → category. Handles names that differ between sheets, e.g. "4406/10" is held in EMBELISHMENT as "Panty", and "RS 26/27" as "RS-27".
B34: Block 3 (rows 32-80) | C34: STYLE × MACHINE MATRIX — the heart of the pack. 48 style rows × 26 machine groups: all 42 EMBELISHMENT styles plus 6 legacy board names (4300/4301, RS 26/27, 4406/10, RS17, THERMAL, VACCANT). Columns AB:AD are a self-audit — the re-grouped total must equal the EMBELISHMENT sheet total, shown as OK. AE = recipe, AF = category, AG = garment type.
B35: Block 4 (rows 85-112) | C35: LINE × MACHINE GROUP for the as-of date. The 26 lines, each given the style it runs that day, exploded across the 26 groups. The total row IS the factory's machine demand on that date.
B36: Block 7 (rows 119-203) | C36: MONTH VIEW — machine groups and styles down, one month of dates across. Pick the month at B120.
B37: Block 9 (CZ4:EV30) | C37: THE MATRIX, TRANSPOSED — machines down, all 48 styles across. Identical numbers to block 3, just rotated, because the daily engine needs to read a machine group as a row. Nothing to maintain; it follows block 3 automatically. DO NOT DELETE.
B39: HOW TO KEEP IT ALIVE — 5 ROUTINES
B40: Every day | C40: Nothing to do. Type or change styles on LINE PLAN and everything downstream re-prices instantly — there is no decode step any more. Just keep an eye on the check cell at LINE PLAN HA2.
B41: Filling a garment type | C41: Go to MC MAP column AG, find the style's row, and PICK from the dropdown. If the garment you want is not offered, add it to the GARMENT MASTER LIST at AJ33:AJ43 first, then pick it. Do not type free text into AG — the dropdown blocks it, because a typo would split the garment rollup into two half-totals. Pink "NEEDS INPUT" cells are the outstanding ones. This affects ONLY the by-garment breakdown; machine counts are correct either way.
B42: New style introduced | C42: (1) Give it a column in EMBELISHMENT with its machine recipe. (2) If the planner's name differs from the EMBELISHMENT heading, add the pairing to the alias table MC MAP K5:M28. (3) Add one row to MC MAP block 3 by copying the row above, and point column A at the new EMBELISHMENT heading. (4) Add the style to the validation list on LINE PLAN column HE (HE5:HE47). (5) Set its garment type in AG. All 42 current EMBELISHMENT styles are already covered.
B43: Machines bought or sold | C43: Update the Available column in MC MASTER only. Machines are keyed by name, so nothing else needs touching — unless a brand-new machine TYPE is added, in which case the 26-machine width of MC MAP blocks 3, 4, 9 and DEMAND BY DATE must be extended.
B44: Extending the date horizon | C44: ONE CELL. Raise LINE PLAN B3 ("DAYS IN PLAN"). Everything follows automatically: the date row, the plan grid, the resolved grid, the changeover flags, the daily engine, the peak-demand block and both dashboards. To shift the whole plan to a different start, change B2 instead. Capacity is built to 200 days — if you ever need more than that, ask me, because the grid width and the daily engine both have to grow. New days default to working, except Sundays; adjust in DEMAND BY DATE column BS.
B46: SELF-CHECKS — WHERE THE PACK TELLS YOU IT IS BROKEN
B47: LINE PLAN HA2 | C47: Unpriceable styles. Green = every planned cell can be costed. Red = the count of cells using a style with no machine recipe. THIS IS THE MOST IMPORTANT CELL IN THE PACK — a style that cannot be priced plans happily and costs zero machines.
...

Sheet MD VIEW
BA1: month idx | BB1: =IFERROR(MATCH($D$4,'DEMAND BY DATE'!$BE$27:$BE$30,0),1) -> 1
B2: MACHINE CAPACITY — MONTHLY DECISION VIEW | BA2: first row | BB2: =INDEX('DEMAND BY DATE'!$BK$27:$BK$30,$BB$1) -> 1
B3: ='LINE PLAN'!$HB$21&" " -> Garment Unit A | BA3: days | BB3: =INDEX('DEMAND BY DATE'!$BL$27:$BL$30,$BB$1) -> 31
B4: MONTH ▾ | D4: August 2026 | BA4: working days | BB4: =INDEX('DEMAND BY DATE'!$BF$27:$BF$30,$BB$1) -> 26
BD5: Group | BE5: Family | BF5: Installed | BG5: Peak | BH5: Gap | BI5: Days short | BJ5: Family spare | BK5: Cover by moving | BL5: Must buy | BM5: rank | BN5: prior claims | BO5: spare rank
B6: Machines installed | D6: Machines required (month peak) | G6: IDLE | J6: Utilisation | M6: Machines to MOVE | P6: Machines to BUY | S6: Days plan won't run | BD6: =INDEX('MC MASTER'!$B$3:$B$28,1) -> SNLS | BE6: =IFERROR(INDEX('MC MAP'!$BX$5:$BX$30,MATCH($BD6,'MC MAP'!$BW$5:$BW$30,0)),"?") -> LOCK-STITCH | BF6: =INDEX('MC MASTER'!$C$3:$C$28,1) -> 185 | BG6: =MAX(OFFSET('DEMAND BY DATE'!$B$4,$BB$2-1,MATCH($BD6,'DEMAND BY DATE'!$B$3:$AA$3,0)-1,$BB$3,1)) -> 152 | BH6: =$BF6-$BG6 -> 33 | BI6: {=SUMPRODUCT((OFFSET('DEMAND BY DATE'!$B$4,$BB$2-1,MATCH($BD6,'DEMAND BY DATE'!$B$3:$AA$3,0)-1,$BB$3,1)>$BF6)*(OFFSET('DEMAND BY DATE'!$BS$4,$BB$2-1,0,$BB$3,1)="Y"))} -> 0 | BJ6: {=SUMPRODUCT(($BE$6:$BE$31=$BE6)*($BH$6:$BH$31>0)*$BH$6:$BH$31)-MAX(0,$BH6)} -> 13 | BK6: =IF($BH6<0,MIN(-$BH6,MAX(0,$BJ6-$BN6)),0) -> 0 | BL6: =IF($BH6<0,-$BH6-$BK6,0) -> 0 | BM6: =$BH6+ROW()/100000 -> 33.00006 | BN6: {=SUMPRODUCT(($BE$6:$BE$31=$BE6)*($BH$6:$BH$31<0)*($BM$6:$BM$31<$BM6)*(-$BH$6:$BH$31))} -> 0 | BO6: =MAX(0,$BH6)-ROW()/100000 -> 32.99994
B7: ='MC MASTER'!$C$29 -> 920 | D7: =INDEX('DEMAND BY DATE'!$BH$27:$BH$30,$BB$1) -> 808 | G7: {=SUMPRODUCT(($BH$6:$BH$31>0)*$BH$6:$BH$31)} -> 121 | J7: =IFERROR($D$7/$B$7,0) -> 0.87826087 | M7: =SUM($BK$6:$BK$31) -> 18.5 | P7: =SUM($BL$6:$BL$31) -> 28 | S7: {=SUMPRODUCT((OFFSET('DEMAND BY DATE'!$AX$4,$BB$2-1,0,$BB$3,1)>0)*1)} -> 26 | BD7: =INDEX('MC MASTER'!$B$3:$B$28,2) -> DNLS | BE7: =IFERROR(INDEX('MC MAP'!$BX$5:$BX$30,MATCH($BD7,'MC MAP'!$BW$5:$BW$30,0)),"?") -> LOCK-STITCH | BF7: =INDEX('MC MASTER'!$C$3:$C$28,2) -> 8 | BG7: =MAX(OFFSET('DEMAND BY DATE'!$B$4,$BB$2-1,MATCH($BD7,'DEMAND BY DATE'!$B$3:$AA$3,0)-1,$BB$3,1)) -> 1 | BH7: =$BF7-$BG7 -> 7 | BI7: {=SUMPRODUCT((OFFSET('DEMAND BY DATE'!$B$4,$BB$2-1,MATCH($BD7,'DEMAND BY DATE'!$B$3:$AA$3,0)-1,$BB$3,1)>$BF7)*(OFFSET('DEMAND BY DATE'!$BS$4,$BB$2-1,0,$BB$3,1)="Y"))} -> 0 | BJ7: {=SUMPRODUCT(($BE$6:$BE$31=$BE7)*($BH$6:$BH$31>0)*$BH$6:$BH$31)-MAX(0,$BH7)} -> 39 | BK7: =IF($BH7<0,MIN(-$BH7,MAX(0,$BJ7-$BN7)),0) -> 0 | BL7: =IF($BH7<0,-$BH7-$BK7,0) -> 0 | BM7: =$BH7+ROW()/100000 -> 7.00007 | BN7: {=SUMPRODUCT(($BE$6:$BE$31=$BE7)*($BH$6:$BH$31<0)*($BM$6:$BM$31<$BM7)*(-$BH$6:$BH$31))} -> 0 | BO7: =MAX(0,$BH7)-ROW()/100000 -> 6.99993
B8: ="In "&$D$4&": peak need "&TEXT($D$7,"#,##0")&" of "&TEXT($B$7,"#,##0")&" machines ("&TEXT($J$7,"0.0%")&"). "&COUNTIF($BH$6:$BH$31,"<0")&" machine types short. Move "&TEXT($M$7,"#,##0.0")&", buy "&TEXT($P$7,"#,##0.0")&". "&TEXT($G$7,"#,##0.0")&" machines idle." -> In August 2026: peak need 808 of 920 machines (87.8%). 6 machine types short. Move 18.5, buy 28.0. 121.0 machines idle. | BD8: =INDEX('MC MASTER'!$B$3:$B$28,3) -> SNLS - Edge cutter | BE8: =IFERROR(INDEX('MC MAP'!$BX$5:$BX$30,MATCH($BD8,'MC MAP'!$BW$5:$BW$30,0)),"?") -> LOCK-STITCH | BF8: =INDEX('MC MASTER'!$C$3:$C$28,3) -> 2 | BG8: =MAX(OFFSET('DEMAND BY DATE'!$B$4,$BB$2-1,MATCH($BD8,'DEMAND BY DATE'!$B$3:$AA$3,0)-1,$BB$3,1)) -> 0 | BH8: =$BF8-$BG8 -> 2 | BI8: {=SUMPRODUCT((OFFSET('DEMAND BY DATE'!$B$4,$BB$2-1,MATCH($BD8,'DEMAND BY DATE'!$B$3:$AA$3,0)-1,$BB$3,1)>$BF8)*(OFFSET('DEMAND BY DATE'!$BS$4,$BB$2-1,0,$BB$3,1)="Y"))} -> 0 | BJ8: {=SUMPRODUCT(($BE$6:$BE$31=$BE8)*($BH$6:$BH$31>0)*$BH$6:$BH$31)-MAX(0,$BH8)} -> 44 | BK8: =IF($BH8<0,MIN(-$BH8,MAX(0,$BJ8-$BN8)),0) -> 0 | BL8: =IF($BH8<0,-$BH8-$BK8,0) -> 0 | BM8: =$BH8+ROW()/100000 -> 2.00008 | BN8: {=SUMPRODUCT(($BE$6:$BE$31=$BE8)*($BH$6:$BH$31<0)*($BM$6:$BM$31<$BM8)*(-$BH$6:$BH$31))} -> 0 | BO8: =MAX(0,$BH8)-ROW()/100000 -> 1.99992
BD9: =INDEX('MC MASTER'!$B$3:$B$28,4) -> Zig - Zag | BE9: =IFERROR(INDEX('MC MAP'!$BX$5:$BX$30,MATCH($BD9,'MC MAP'!$BW$5:$BW$30,0)),"?") -> LOCK-STITCH | BF9: =INDEX('MC MASTER'!$C$3:$C$28,4) -> 8 | BG9: =MAX(OFFSET('DEMAND BY DATE'!$B$4,$BB$2-1,MATCH($BD9,'DEMAND BY DATE'!$B$3:$AA$3,0)-1,$BB$3,1)) -> 4 | BH9: =$BF9-$BG9 -> 4 | BI9: {=SUMPRODUCT((OFFSET('DEMAND BY DATE'!$B$4,$BB$2-1,MATCH($BD9,'DEMAND BY DATE'!$B$3:$AA$3,0)-1,$BB$3,1)>$BF9)*(OFFSET('DEMAND BY DATE'!$BS$4,$BB$2-1,0,$BB$3,1)="Y"))} -> 0 | BJ9: {=SUMPRODUCT(($BE$6:$BE$31=$BE9)*($BH$6:$BH$31>0)*$BH$6:$BH$31)-MAX(0,$BH9)} -> 42 | BK9: =IF($BH9<0,MIN(-$BH9,MAX(0,$BJ9-$BN9)),0) -> 0 | BL9: =IF($BH9<0,-$BH9-$BK9,0) -> 0 | BM9: =$BH9+ROW()/100000 -> 4.00009 | BN9: {=SUMPRODUCT(($BE$6:$BE$31=$BE9)*($BH$6:$BH$31<0)*($BM$6:$BM$31<$BM9)*(-$BH$6:$BH$31))} -> 0 | BO9: =MAX(0,$BH9)-ROW()/100000 -> 3.99991
B10: ="MACHINE CAPACITY - "& TEXT(D4,"mmmm yyyy") -> MACHINE CAPACITY - August 2026 | BD10: =INDEX('MC MASTER'!$B$3:$B$28,5) -> 4th Overlock | BE10: =IFERROR(INDEX('MC MAP'!$BX$5:$BX$30,MATCH($BD10,'MC MAP'!$BW$5:$BW$30,0)),"?") -> OVER-LOCK | BF10: =INDEX('MC MASTER'!$C$3:$C$28,5) -> 279 | BG10: =MAX(OFFSET('DEMAND BY DATE'!$B$4,$BB$2-1,MATCH($BD10,'DEMAND BY DATE'!$B$3:$AA$3,0)-1,$BB$3,1)) -> 291 | BH10: =$BF10-$BG10 -> -12 | BI10: {=SUMPRODUCT((OFFSET('DEMAND BY DATE'!$B$4,$BB$2-1,MATCH($BD10,'DEMAND BY DATE'!$B$3:$AA$3,0)-1,$BB$3,1)>$BF10)*(OFFSET('DEMAND BY DATE'!$BS$4,$BB$2-1,0,$BB$3,1)="Y"))} -> 11 | BJ10: {=SUMPRODUCT(($BE$6:$BE$31=$BE10)*($BH$6:$BH$31>0)*$BH$6:$BH$31)-MAX(0,$BH10)} -> 5 | BK10: =IF($BH10<0,MIN(-$BH10,MAX(0,$BJ10-$BN10)),0) -> 5 | BL10: =IF($BH10<0,-$BH10-$BK10,0) -> 7 | BM10: =$BH10+ROW()/100000 -> -11.9999 | BN10: {=SUMPRODUCT(($BE$6:$BE$31=$BE10)*($BH$6:$BH$31<0)*($BM$6:$BM$31<$BM10)*(-$BH$6:$BH$31))} -> 0 | BO10: =MAX(0,$BH10)-ROW()/100000 -> -0.0001
B11: Category | C11: Machine | D11: Own | E11: =IF(1>$BB$3,"",INDEX('DEMAND BY DATE'!$A$4:$A$203,$BB$2+0)) -> 46235 | F11: =IF(2>$BB$3,"",INDEX('DEMAND BY DATE'!$A$4:$A$203,$BB$2+1)) -> 46236 | G11: =IF(3>$BB$3,"",INDEX('DEMAND BY DATE'!$A$4:$A$203,$BB$2+2)) -> 46237 | H11: =IF(4>$BB$3,"",INDEX('DEMAND BY DATE'!$A$4:$A$203,$BB$2+3)) -> 46238 | I11: =IF(5>$BB$3,"",INDEX('DEMAND BY DATE'!$A$4:$A$203,$BB$2+4)) -> 46239 | J11: =IF(6>$BB$3,"",INDEX('DEMAND BY DATE'!$A$4:$A$203,$BB$2+5)) -> 46240 | K11: =IF(7>$BB$3,"",INDEX('DEMAND BY DATE'!$A$4:$A$203,$BB$2+6)) -> 46241 | L11: =IF(8>$BB$3,"",INDEX('DEMAND BY DATE'!$A$4:$A$203,$BB$2+7)) -> 46242 | M11: =IF(9>$BB$3,"",INDEX('DEMAND BY DATE'!$A$4:$A$203,$BB$2+8)) -> 46243 | N11: =IF(10>$BB$3,"",INDEX('DEMAND BY DATE'!$A$4:$A$203,$BB$2+9)) -> 46244 | O11: =IF(11>$BB$3,"",INDEX('DEMAND BY DATE'!$A$4:$A$203,$BB$2+10)) -> 46245 | P11: =IF(12>$BB$3,"",INDEX('DEMAND BY DATE'!$A$4:$A$203,$BB$2+11)) -> 46246 | Q11: =IF(13>$BB$3,"",INDEX('DEMAND BY DATE'!$A$4:$A$203,$BB$2+12)) -> 46247 | R11: =IF(14>$BB$3,"",INDEX('DEMAND BY DATE'!$A$4:$A$203,$BB$2+13)) -> 46248 | S11: =IF(15>$BB$3,"",INDEX('DEMAND BY DATE'!$A$4:$A$203,$BB$2+14)) -> 46249 | T11: =IF(16>$BB$3,"",INDEX('DEMAND BY DATE'!$A$4:$A$203,$BB$2+15)) -> 46250 | U11: =IF(17>$BB$3,"",INDEX('DEMAND BY DATE'!$A$4:$A$203,$BB$2+16)) -> 46251 | V11: =IF(18>$BB$3,"",INDEX('DEMAND BY DATE'!$A$4:$A$203,$BB$2+17)) -> 46252 | W11: =IF(19>$BB$3,"",INDEX('DEMAND BY DATE'!$A$4:$A$203,$BB$2+18)) -> 46253 | X11: =IF(20>$BB$3,"",INDEX('DEMAND BY DATE'!$A$4:$A$203,$BB$2+19)) -> 46254 | Y11: =IF(21>$BB$3,"",INDEX('DEMAND BY DATE'!$A$4:$A$203,$BB$2+20)) -> 46255 | Z11: =IF(22>$BB$3,"",INDEX('DEMAND BY DATE'!$A$4:$A$203,$BB$2+21)) -> 46256 | AA11: =IF(23>$BB$3,"",INDEX('DEMAND BY DATE'!$A$4:$A$203,$BB$2+22)) -> 46257 | AB11: =IF(24>$BB$3,"",INDEX('DEMAND BY DATE'!$A$4:$A$203,$BB$2+23)) -> 46258 | AC11: =IF(25>$BB$3,"",INDEX('DEMAND BY DATE'!$A$4:$A$203,$BB$2+24)) -> 46259 | AD11: =IF(26>$BB$3,"",INDEX('DEMAND BY DATE'!$A$4:$A$203,$BB$2+25)) -> 46260 | AE11: =IF(27>$BB$3,"",INDEX('DEMAND BY DATE'!$A$4:$A$203,$BB$2+26)) -> 46261 | AF11: =IF(28>$BB$3,"",INDEX('DEMAND BY DATE'!$A$4:$A$203,$BB$2+27)) -> 46262 | AG11: =IF(29>$BB$3,"",INDEX('DEMAND BY DATE'!$A$4:$A$203,$BB$2+28)) -> 46263 | AH11: =IF(30>$BB$3,"",INDEX('DEMAND BY DATE'!$A$4:$A$203,$BB$2+29)) -> 46264 | AI11: =IF(31>$BB$3,"",INDEX('DEMAND BY DATE'!$A$4:$A$203,$BB$2+30)) -> 46265 | BD11: =INDEX('MC MASTER'!$B$3:$B$28,6) -> 3th Overlock (Leg elastic) | BE11: =IFERROR(INDEX('MC MAP'!$BX$5:$BX$30,MATCH($BD11,'MC MAP'!$BW$5:$BW$30,0)),"?") -> OVER-LOCK | BF11: =INDEX('MC MASTER'!$C$3:$C$28,6) -> 30 | BG11: =MAX(OFFSET('DEMAND BY DATE'!$B$4,$BB$2-1,MATCH($BD11,'DEMAND BY DATE'!$B$3:$AA$3,0)-1,$BB$3,1)) -> 31 | BH11: =$BF11-$BG11 -> -1 | BI11: {=SUMPRODUCT((OFFSET('DEMAND BY DATE'!$B$4,$BB$2-1,MATCH($BD11,'DEMAND BY DATE'!$B$3:$AA$3,0)-1,$BB$3,1)>$BF11)*(OFFSET('DEMAND BY DATE'!$BS$4,$BB$2-1,0,$BB$3,1)="Y"))} -> 11 | BJ11: {=SUMPRODUCT(($BE$6:$BE$31=$BE11)*($BH$6:$BH$31>0)*$BH$6:$BH$31)-MAX(0,$BH11)} -> 5 | BK11: =IF($BH11<0,MIN(-$BH11,MAX(0,$BJ11-$BN11)),0) -> 0 | BL11: =IF($BH11<0,-$BH11-$BK11,0) -> 1 | BM11: =$BH11+ROW()/100000 -> -0.99989 | BN11: {=SUMPRODUCT(($BE$6:$BE$31=$BE11)*($BH$6:$BH$31<0)*($BM$6:$BM$31<$BM11)*(-$BH$6:$BH$31))} -> 19 | BO11: =MAX(0,$BH11)-ROW()/100000 -> -0.00011
B12: =IFERROR(INDEX(WORKINGS!$B$116:$B$141,MATCH($C12,WORKINGS!$A$116:$A$141,0)),"") -> LOCK-STITCH | C12: =INDEX(WORKINGS!$A$116:$A$141,MATCH(SMALL(WORKINGS!$D$116:$D$141,1),WORKINGS!$D$116:$D$141,0)) -> SNLS | D12: =IFERROR(INDEX($BF$6:$BF$31,MATCH($C12,$BD$6:$BD$31,0)),0) -> 185 | E12: =IF(E$11="","",IFERROR($D12-INDEX('DEMAND BY DATE'!$B$4:$AA$203,MATCH(E$11,'DEMAND BY DATE'!$A$4:$A$203,0),MATCH($C12,'DEMAND BY DATE'!$B$3:$AA$3,0)),"")) -> 33 | F12: =IF(F$11="","",IFERROR($D12-INDEX('DEMAND BY DATE'!$B$4:$AA$203,MATCH(F$11,'DEMAND BY DATE'!$A$4:$A$203,0),MATCH($C12,'DEMAND BY DATE'!$B$3:$AA$3,0)),"")) -> 33 | G12: =IF(G$11="","",IFERROR($D12-INDEX('DEMAND BY DATE'!$B$4:$AA$203,MATCH(G$11,'DEMAND BY DATE'!$A$4:$A$203,0),MATCH($C12,'DEMAND BY DATE'!$B$3:$AA$3,0)),"")) -> 33 | H12: =IF(H$11="","",IFERROR($D12-INDEX('DEMAND BY DATE'!$B$4:$AA$203,MATCH(H$11,'DEMAND BY DATE'!$A$4:$A$203,0),MATCH($C12,'DEMAND BY DATE'!$B$3:$AA$3,0)),"")) -> 33 | I12: =IF(I$11="","",IFERROR($D12-INDEX('DEMAND BY DATE'!$B$4:$AA$203,MATCH(I$11,'DEMAND BY DATE'!$A$4:$A$203,0),MATCH($C12,'DEMAND BY DATE'!$B$3:$AA$3,0)),"")) -> 33 | J12: =IF(J$11="","",IFERROR($D12-INDEX('DEMAND BY DATE'!$B$4:$AA$203,MATCH(J$11,'DEMAND BY DATE'!$A$4:$A$203,0),MATCH($C12,'DEMAND BY DATE'!$B$3:$AA$3,0)),"")) -> 33 | K12: =IF(K$11="","",IFERROR($D12-INDEX('DEMAND BY DATE'!$B$4:$AA$203,MATCH(K$11,'DEMAND BY DATE'!$A$4:$A$203,0),MATCH($C12,'DEMAND BY DATE'!$B$3:$AA$3,0)),"")) -> 33 | L12: =IF(L$11="","",IFERROR($D12-INDEX('DEMAND BY DATE'!$B$4:$AA$203,MATCH(L$11,'DEMAND BY DATE'!$A$4:$A$203,0),MATCH($C12,'DEMAND BY DATE'!$B$3:$AA$3,0)),"")) -> 33 | ... AI12: =IF(AI$11="","",IFERROR($D12-INDEX('DEMAND BY DATE'!$B$4:$AA$203,MATCH(AI$11,'DEMAND BY DATE'!$A$4:$A$203,0),MATCH($C12,'DEMAND BY DATE'!$B$3:$AA$3,0)),"")) -> 40.5 | BD12: =INDEX('MC MASTER'!$B$3:$B$28,7) -> 5th Overlock | BE12: =IFERROR(INDEX('MC MAP'!$BX$5:$BX$30,MATCH($BD12,'MC MAP'!$BW$5:$BW$30,0)),"?") -> OVER-LOCK | BF12: =INDEX('MC MASTER'!$C$3:$C$28,7) -> 5 | BG12: =MAX(OFFSET('DEMAND BY DATE'!$B$4,$BB$2-1,MATCH($BD12,'DEMAND BY DATE'!$B$3:$AA$3,0)-1,$BB$3,1)) -> 0 | BH12: =$BF12-$BG12 -> 5 | BI12: {=SUMPRODUCT((OFFSET('DEMAND BY DATE'!$B$4,$BB$2-1,MATCH($BD12,'DEMAND BY DATE'!$B$3:$AA$3,0)-1,$BB$3,1)>$BF12)*(OFFSET('DEMAND BY DATE'!$BS$4,$BB$2-1,0,$BB$3,1)="Y"))} -> 0 | BJ12: {=SUMPRODUCT(($BE$6:$BE$31=$BE12)*($BH$6:$BH$31>0)*$BH$6:$BH$31)-MAX(0,$BH12)} -> 0 | BK12: =IF($BH12<0,MIN(-$BH12,MAX(0,$BJ12-$BN12)),0) -> 0 | BL12: =IF($BH12<0,-$BH12-$BK12,0) -> 0 | BM12: =$BH12+ROW()/100000 -> 5.00012 | BN12: {=SUMPRODUCT(($BE$6:$BE$31=$BE12)*($BH$6:$BH$31<0)*($BM$6:$BM$31<$BM12)*(-$BH$6:$BH$31))} -> 20 | BO12: =MAX(0,$BH12)-ROW()/100000 -> 4.99988
B13: =IFERROR(INDEX(WORKINGS!$B$116:$B$141,MATCH($C13,WORKINGS!$A$116:$A$141,0)),"") -> LOCK-STITCH | C13: =INDEX(WORKINGS!$A$116:$A$141,MATCH(SMALL(WORKINGS!$D$116:$D$141,2),WORKINGS!$D$116:$D$141,0)) -> DNLS | D13: =IFERROR(INDEX($BF$6:$BF$31,MATCH($C13,$BD$6:$BD$31,0)),0) -> 8 | E13: =IF(E$11="","",IFERROR($D13-INDEX('DEMAND BY DATE'!$B$4:$AA$203,MATCH(E$11,'DEMAND BY DATE'!$A$4:$A$203,0),MATCH($C13,'DEMAND BY DATE'!$B$3:$AA$3,0)),"")) -> 7 | F13: =IF(F$11="","",IFERROR($D13-INDEX('DEMAND BY DATE'!$B$4:$AA$203,MATCH(F$11,'DEMAND BY DATE'!$A$4:$A$203,0),MATCH($C13,'DEMAND BY DATE'!$B$3:$AA$3,0)),"")) -> 7 | G13: =IF(G$11="","",IFERROR($D13-INDEX('DEMAND BY DATE'!$B$4:$AA$203,MATCH(G$11,'DEMAND BY DATE'!$A$4:$A$203,0),MATCH($C13,'DEMAND BY DATE'!$B$3:$AA$3,0)),"")) -> 7 | H13: =IF(H$11="","",IFERROR($D13-INDEX('DEMAND BY DATE'!$B$4:$AA$203,MATCH(H$11,'DEMAND BY DATE'!$A$4:$A$203,0),MATCH($C13,'DEMAND BY DATE'!$B$3:$AA$3,0)),"")) -> 7 | I13: =IF(I$11="","",IFERROR($D13-INDEX('DEMAND BY DATE'!$B$4:$AA$203,MATCH(I$11,'DEMAND BY DATE'!$A$4:$A$203,0),MATCH($C13,'DEMAND BY DATE'!$B$3:$AA$3,0)),"")) -> 7 | J13: =IF(J$11="","",IFERROR($D13-INDEX('DEMAND BY DATE'!$B$4:$AA$203,MATCH(J$11,'DEMAND BY DATE'!$A$4:$A$203,0),MATCH($C13,'DEMAND BY DATE'!$B$3:$AA$3,0)),"")) -> 7 | K13: =IF(K$11="","",IFERROR($D13-INDEX('DEMAND BY DATE'!$B$4:$AA$203,MATCH(K$11,'DEMAND BY DATE'!$A$4:$A$203,0),MATCH($C13,'DEMAND BY DATE'!$B$3:$AA$3,0)),"")) -> 7 | L13: =IF(L$11="","",IFERROR($D13-INDEX('DEMAND BY DATE'!$B$4:$AA$203,MATCH(L$11,'DEMAND BY DATE'!$A$4:$A$203,0),MATCH($C13,'DEMAND BY DATE'!$B$3:$AA$3,0)),"")) -> 7 | ... AI13: =IF(AI$11="","",IFERROR($D13-INDEX('DEMAND BY DATE'!$B$4:$AA$203,MATCH(AI$11,'DEMAND BY DATE'!$A$4:$A$203,0),MATCH($C13,'DEMAND BY DATE'!$B$3:$AA$3,0)),"")) -> 7 | BD13: =INDEX('MC MASTER'!$B$3:$B$28,8) -> Overlock (Ring Elastic Attach) | BE13: =IFERROR(INDEX('MC MAP'!$BX$5:$BX$30,MATCH($BD13,'MC MAP'!$BW$5:$BW$30,0)),"?") -> OVER-LOCK | BF13: =INDEX('MC MASTER'!$C$3:$C$28,8) -> 29 | BG13: =MAX(OFFSET('DEMAND BY DATE'!$B$4,$BB$2-1,MATCH($BD13,'DEMAND BY DATE'!$B$3:$AA$3,0)-1,$BB$3,1)) -> 36 | BH13: =$BF13-$BG13 -> -7 | BI13: {=SUMPRODUCT((OFFSET('DEMAND BY DATE'!$B$4,$BB$2-1,MATCH($BD13,'DEMAND BY DATE'!$B$3:$AA$3,0)-1,$BB$3,1)>$BF13)*(OFFSET('DEMAND BY DATE'!$BS$4,$BB$2-1,0,$BB$3,1)="Y"))} -> 26 | BJ13: {=SUMPRODUCT(($BE$6:$BE$31=$BE13)*($BH$6:$BH$31>0)*$BH$6:$BH$31)-MAX(0,$BH13)} -> 5 | BK13: =IF($BH13<0,MIN(-$BH13,MAX(0,$BJ13-$BN13)),0) -> 0 | BL13: =IF($BH13<0,-$BH13-$BK13,0) -> 7 | BM13: =$BH13+ROW()/100000 -> -6.99987 | BN13: {=SUMPRODUCT(($BE$6:$BE$31=$BE13)*($BH$6:$BH$31<0)*($BM$6:$BM$31<$BM13)*(-$BH$6:$BH$31))} -> 12 | BO13: =MAX(0,$BH13)-ROW()/100000 -> -0.00013
B14: =IFERROR(INDEX(WORKINGS!$B$116:$B$141,MATCH($C14,WORKINGS!$A$116:$A$141,0)),"") -> LOCK-STITCH | C14: =INDEX(WORKINGS!$A$116:$A$141,MATCH(SMALL(WORKINGS!$D$116:$D$141,3),WORKINGS!$D$116:$D$141,0)) -> SNLS - Edge cutter | D14: =IFERROR(INDEX($BF$6:$BF$31,MATCH($C14,$BD$6:$BD$31,0)),0) -> 2 | E14: =IF(E$11="","",IFERROR($D14-INDEX('DEMAND BY DATE'!$B$4:$AA$203,MATCH(E$11,'DEMAND BY DATE'!$A$4:$A$203,0),MATCH($C14,'DEMAND BY DATE'!$B$3:$AA$3,0)),"")) -> 2 | F14: =IF(F$11="","",IFERROR($D14-INDEX('DEMAND BY DATE'!$B$4:$AA$203,MATCH(F$11,'DEMAND BY DATE'!$A$4:$A$203,0),MATCH($C14,'DEMAND BY DATE'!$B$3:$AA$3,0)),"")) -> 2 | G14: =IF(G$11="","",IFERROR($D14-INDEX('DEMAND BY DATE'!$B$4:$AA$203,MATCH(G$11,'DEMAND BY DATE'!$A$4:$A$203,0),MATCH($C14,'DEMAND BY DATE'!$B$3:$AA$3,0)),"")) -> 2 | H14: =IF(H$11="","",IFERROR($D14-INDEX('DEMAND BY DATE'!$B$4:$AA$203,MATCH(H$11,'DEMAND BY DATE'!$A$4:$A$203,0),MATCH($C14,'DEMAND BY DATE'!$B$3:$AA$3,0)),"")) -> 2 | I14: =IF(I$11="","",IFERROR($D14-INDEX('DEMAND BY DATE'!$B$4:$AA$203,MATCH(I$11,'DEMAND BY DATE'!$A$4:$A$203,0),MATCH($C14,'DEMAND BY DATE'!$B$3:$AA$3,0)),"")) -> 2 | J14: =IF(J$11="","",IFERROR($D14-INDEX('DEMAND BY DATE'!$B$4:$AA$203,MATCH(J$11,'DEMAND BY DATE'!$A$4:$A$203,0),MATCH($C14,'DEMAND BY DATE'!$B$3:$AA$3,0)),"")) -> 2 | K14: =IF(K$11="","",IFERROR($D14-INDEX('DEMAND BY DATE'!$B$4:$AA$203,MATCH(K$11,'DEMAND BY DATE'!$A$4:$A$203,0),MATCH($C14,'DEMAND BY DATE'!$B$3:$AA$3,0)),"")) -> 2 | L14: =IF(L$11="","",IFERROR($D14-INDEX('DEMAND BY DATE'!$B$4:$AA$203,MATCH(L$11,'DEMAND BY DATE'!$A$4:$A$203,0),MATCH($C14,'DEMAND BY DATE'!$B$3:$AA$3,0)),"")) -> 2 | ... AI14: =IF(AI$11="","",IFERROR($D14-INDEX('DEMAND BY DATE'!$B$4:$AA$203,MATCH(AI$11,'DEMAND BY DATE'!$A$4:$A$203,0),MATCH($C14,'DEMAND BY DATE'!$B$3:$AA$3,0)),"")) -> 2 | BD14: =INDEX('MC MASTER'!$B$3:$B$28,9) -> Flatlock Hem | BE14: =IFERROR(INDEX('MC MAP'!$BX$5:$BX$30,MATCH($BD14,'MC MAP'!$BW$5:$BW$30,0)),"?") -> FLAT-LOCK | BF14: =INDEX('MC MASTER'!$C$3:$C$28,9) -> 34 | BG14: =MAX(OFFSET('DEMAND BY DATE'!$B$4,$BB$2-1,MATCH($BD14,'DEMAND BY DATE'!$B$3:$AA$3,0)-1,$BB$3,1)) -> 27.5 | BH14: =$BF14-$BG14 -> 6.5 | BI14: {=SUMPRODUCT((OFFSET('DEMAND BY DATE'!$B$4,$BB$2-1,MATCH($BD14,'DEMAND BY DATE'!$B$3:$AA$3,0)-1,$BB$3,1)>$BF14)*(OFFSET('DEMAND BY DATE'!$BS$4,$BB$2-1,0,$BB$3,1)="Y"))} -> 0 | BJ14: {=SUMPRODUCT(($BE$6:$BE$31=$BE14)*($BH$6:$BH$31>0)*$BH$6:$BH$31)-MAX(0,$BH14)} -> 7 | BK14: =IF($BH14<0,MIN(-$BH14,MAX(0,$BJ14-$BN14)),0) -> 0 | BL14: =IF($BH14<0,-$BH14-$BK14,0) -> 0 | BM14: =$BH14+ROW()/100000 -> 6.50014 | BN14: {=SUMPRODUCT(($BE$6:$BE$31=$BE14)*($BH$6:$BH$31<0)*($BM$6:$BM$31<$BM14)*(-$BH$6:$BH$31))} -> 26.5 | BO14: =MAX(0,$BH14)-ROW()/100000 -> 6.49986
B15: =IFERROR(INDEX(WORKINGS!$B$116:$B$141,MATCH($C15,WORKINGS!$A$116:$A$141,0)),"") -> LOCK-STITCH | C15: =INDEX(WORKINGS!$A$116:$A$141,MATCH(SMALL(WORKINGS!$D$116:$D$141,4),WORKINGS!$D$116:$D$141,0)) -> Zig - Zag | D15: =IFERROR(INDEX($BF$6:$BF$31,MATCH($C15,$BD$6:$BD$31,0)),0) -> 8 | E15: =IF(E$11="","",IFERROR($D15-INDEX('DEMAND BY DATE'!$B$4:$AA$203,MATCH(E$11,'DEMAND BY DATE'!$A$4:$A$203,0),MATCH($C15,'DEMAND BY DATE'!$B$3:$AA$3,0)),"")) -> 4 | F15: =IF(F$11="","",IFERROR($D15-INDEX('DEMAND BY DATE'!$B$4:$AA$203,MATCH(F$11,'DEMAND BY DATE'!$A$4:$A$203,0),MATCH($C15,'DEMAND BY DATE'!$B$3:$AA$3,0)),"")) -> 4 | G15: =IF(G$11="","",IFERROR($D15-INDEX('DEMAND BY DATE'!$B$4:$AA$203,MATCH(G$11,'DEMAND BY DATE'!$A$4:$A$203,0),MATCH($C15,'DEMAND BY DATE'!$B$3:$AA$3,0)),"")) -> 4 | H15: =IF(H$11="","",IFERROR($D15-INDEX('DEMAND BY DATE'!$B$4:$AA$203,MATCH(H$11,'DEMAND BY DATE'!$A$4:$A$203,0),MATCH($C15,'DEMAND BY DATE'!$B$3:$AA$3,0)),"")) -> 4 | I15: =IF(I$11="","",IFERROR($D15-INDEX('DEMAND BY DATE'!$B$4:$AA$203,MATCH(I$11,'DEMAND BY DATE'!$A$4:$A$203,0),MATCH($C15,'DEMAND BY DATE'!$B$3:$AA$3,0)),"")) -> 4 | J15: =IF(J$11="","",IFERROR($D15-INDEX('DEMAND BY DATE'!$B$4:$AA$203,MATCH(J$11,'DEMAND BY DATE'!$A$4:$A$203,0),MATCH($C15,'DEMAND BY DATE'!$B$3:$AA$3,0)),"")) -> 4 | K15: =IF(K$11="","",IFERROR($D15-INDEX('DEMAND BY DATE'!$B$4:$AA$203,MATCH(K$11,'DEMAND BY DATE'!$A$4:$A$203,0),MATCH($C15,'DEMAND BY DATE'!$B$3:$AA$3,0)),"")) -> 4 | L15: =IF(L$11="","",IFERROR($D15-INDEX('DEMAND BY DATE'!$B$4:$AA$203,MATCH(L$11,'DEMAND BY DATE'!$A$4:$A$203,0),MATCH($C15,'DEMAND BY DATE'!$B$3:$AA$3,0)),"")) -> 4 | ... AI15: =IF(AI$11="","",IFERROR($D15-INDEX('DEMAND BY DATE'!$B$4:$AA$203,MATCH(AI$11,'DEMAND BY DATE'!$A$4:$A$203,0),MATCH($C15,'DEMAND BY DATE'!$B$3:$AA$3,0)),"")) -> 4 | BD15: =INDEX('MC MASTER'!$B$3:$B$28,10) -> F/L (Coverseam / Waist COVER SEAM | BE15: =IFERROR(INDEX('MC MAP'!$BX$5:$BX$30,MATCH($BD15,'MC MAP'!$BW$5:$BW$30,0)),"?") -> FLAT-LOCK | BF15: =INDEX('MC MASTER'!$C$3:$C$28,10) -> 13 | BG15: =MAX(OFFSET('DEMAND BY DATE'!$B$4,$BB$2-1,MATCH($BD15,'DEMAND BY DATE'!$B$3:$AA$3,0)-1,$BB$3,1)) -> 12 | BH15: =$BF15-$BG15 -> 1 | BI15: {=SUMPRODUCT((OFFSET('DEMAND BY DATE'!$B$4,$BB$2-1,MATCH($BD15,'DEMAND BY DATE'!$B$3:$AA$3,0)-1,$BB$3,1)>$BF15)*(OFFSET('DEMAND BY DATE'!$BS$4,$BB$2-1,0,$BB$3,1)="Y"))} -> 0 | BJ15: {=SUMPRODUCT(($BE$6:$BE$31=$BE15)*($BH$6:$BH$31>0)*$BH$6:$BH$31)-MAX(0,$BH15)} -> 12.5 | BK15: =IF($BH15<0,MIN(-$BH15,MAX(0,$BJ15-$BN15)),0) -> 0 | BL15: =IF($BH15<0,-$BH15-$BK15,0) -> 0 | BM15: =$BH15+ROW()/100000 -> 1.00015 | BN15: {=SUMPRODUCT(($BE$6:$BE$31=$BE15)*($BH$6:$BH$31<0)*($BM$6:$BM$31<$BM15)*(-$BH$6:$BH$31))} -> 26.5 | BO15: =MAX(0,$BH15)-ROW()/100000 -> 0.99985
B16: =IFERROR(INDEX(WORKINGS!$B$116:$B$141,MATCH($C16,WORKINGS!$A$116:$A$141,0)),"") -> OVER-LOCK | C16: =INDEX(WORKINGS!$A$116:$A$141,MATCH(SMALL(WORKINGS!$D$116:$D$141,5),WORKINGS!$D$116:$D$141,0)) -> 4th Overlock | D16: =IFERROR(INDEX($BF$6:$BF$31,MATCH($C16,$BD$6:$BD$31,0)),0) -> 279 | E16: =IF(E$11="","",IFERROR($D16-INDEX('DEMAND BY DATE'!$B$4:$AA$203,MATCH(E$11,'DEMAND BY DATE'!$A$4:$A$203,0),MATCH($C16,'DEMAND BY DATE'!$B$3:$AA$3,0)),"")) -> -12 | F16: =IF(F$11="","",IFERROR($D16-INDEX('DEMAND BY DATE'!$B$4:$AA$203,MATCH(F$11,'DEMAND BY DATE'!$A$4:$A$203,0),MATCH($C16,'DEMAND BY DATE'!$B$3:$AA$3,0)),"")) -> -12 | G16: =IF(G$11="","",IFERROR($D16-INDEX('DEMAND BY DATE'!$B$4:$AA$203,MATCH(G$11,'DEMAND BY DATE'!$A$4:$A$203,0),MATCH($C16,'DEMAND BY DATE'!$B$3:$AA$3,0)),"")) -> -12 | H16: =IF(H$11="","",IFERROR($D16-INDEX('DEMAND BY DATE'!$B$4:$AA$203,MATCH(H$11,'DEMAND BY DATE'!$A$4:$A$203,0),MATCH($C16,'DEMAND BY DATE'!$B$3:$AA$3,0)),"")) -> -12 | I16: =IF(I$11="","",IFERROR($D16-INDEX('DEMAND BY DATE'!$B$4:$AA$203,MATCH(I$11,'DEMAND BY DATE'!$A$4:$A$203,0),MATCH($C16,'DEMAND BY DATE'!$B$3:$AA$3,0)),"")) -> -12 | J16: =IF(J$11="","",IFERROR($D16-INDEX('DEMAND BY DATE'!$B$4:$AA$203,MATCH(J$11,'DEMAND BY DATE'!$A$4:$A$203,0),MATCH($C16,'DEMAND BY DATE'!$B$3:$AA$3,0)),"")) -> -12 | K16: =IF(K$11="","",IFERROR($D16-INDEX('DEMAND BY DATE'!$B$4:$AA$203,MATCH(K$11,'DEMAND BY DATE'!$A$4:$A$203,0),MATCH($C16,'DEMAND BY DATE'!$B$3:$AA$3,0)),"")) -> -12 | L16: =IF(L$11="","",IFERROR($D16-INDEX('DEMAND BY DATE'!$B$4:$AA$203,MATCH(L$11,'DEMAND BY DATE'!$A$4:$A$203,0),MATCH($C16,'DEMAND BY DATE'!$B$3:$AA$3,0)),"")) -> -12 | ... AI16: =IF(AI$11="","",IFERROR($D16-INDEX('DEMAND BY DATE'!$B$4:$AA$203,MATCH(AI$11,'DEMAND BY DATE'!$A$4:$A$203,0),MATCH($C16,'DEMAND BY DATE'!$B$3:$AA$3,0)),"")) -> 13 | BD16: =INDEX('MC MASTER'!$B$3:$B$28,11) -> F/L (Coverseam )with pullar | BE16: =IFERROR(INDEX('MC MAP'!$BX$5:$BX$30,MATCH($BD16,'MC MAP'!$BW$5:$BW$30,0)),"?") -> FLAT-LOCK | BF16: =INDEX('MC MASTER'!$C$3:$C$28,11) -> 37 | BG16: =MAX(OFFSET('DEMAND BY DATE'!$B$4,$BB$2-1,MATCH($BD16,'DEMAND BY DATE'!$B$3:$AA$3,0)-1,$BB$3,1)) -> 43.5 | BH16: =$BF16-$BG16 -> -6.5 | BI16: {=SUMPRODUCT((OFFSET('DEMAND BY DATE'!$B$4,$BB$2-1,MATCH($BD16,'DEMAND BY DATE'!$B$3:$AA$3,0)-1,$BB$3,1)>$BF16)*(OFFSET('DEMAND BY DATE'!$BS$4,$BB$2-1,0,$BB$3,1)="Y"))} -> 25 | BJ16: {=SUMPRODUCT(($BE$6:$BE$31=$BE16)*($BH$6:$BH$31>0)*$BH$6:$BH$31)-MAX(0,$BH16)} -> 13.5 | BK16: =IF($BH16<0,MIN(-$BH16,MAX(0,$BJ16-$BN16)),0) -> 0 | BL16: =IF($BH16<0,-$BH16-$BK16,0) -> 6.5 | BM16: =$BH16+ROW()/100000 -> -6.49984 | BN16: {=SUMPRODUCT(($BE$6:$BE$31=$BE16)*($BH$6:$BH$31<0)*($BM$6:$BM$31<$BM16)*(-$BH$6:$BH$31))} -> 20 | BO16: =MAX(0,$BH16)-ROW()/100000 -> -0.00016
B17: =IFERROR(INDEX(WORKINGS!$B$116:$B$141,MATCH($C17,WORKINGS!$A$116:$A$141,0)),"") -> OVER-LOCK | C17: =INDEX(WORKINGS!$A$116:$A$141,MATCH(SMALL(WORKINGS!$D$116:$D$141,6),WORKINGS!$D$116:$D$141,0)) -> 3th Overlock (Leg elastic) | D17: =IFERROR(INDEX($BF$6:$BF$31,MATCH($C17,$BD$6:$BD$31,0)),0) -> 30 | E17: =IF(E$11="","",IFERROR($D17-INDEX('DEMAND BY DATE'!$B$4:$AA$203,MATCH(E$11,'DEMAND BY DATE'!$A$4:$A$203,0),MATCH($C17,'DEMAND BY DATE'!$B$3:$AA$3,0)),"")) -> -1 | F17: =IF(F$11="","",IFERROR($D17-INDEX('DEMAND BY DATE'!$B$4:$AA$203,MATCH(F$11,'DEMAND BY DATE'!$A$4:$A$203,0),MATCH($C17,'DEMAND BY DATE'!$B$3:$AA$3,0)),"")) -> -1 | G17: =IF(G$11="","",IFERROR($D17-INDEX('DEMAND BY DATE'!$B$4:$AA$203,MATCH(G$11,'DEMAND BY DATE'!$A$4:$A$203,0),MATCH($C17,'DEMAND BY DATE'!$B$3:$AA$3,0)),"")) -> -1 | H17: =IF(H$11="","",IFERROR($D17-INDEX('DEMAND BY DATE'!$B$4:$AA$203,MATCH(H$11,'DEMAND BY DATE'!$A$4:$A$203,0),MATCH($C17,'DEMAND BY DATE'!$B$3:$AA$3,0)),"")) -> -1 | I17: =IF(I$11="","",IFERROR($D17-INDEX('DEMAND BY DATE'!$B$4:$AA$203,MATCH(I$11,'DEMAND BY DATE'!$A$4:$A$203,0),MATCH($C17,'DEMAND BY DATE'!$B$3:$AA$3,0)),"")) -> -1 | J17: =IF(J$11="","",IFERROR($D17-INDEX('DEMAND BY DATE'!$B$4:$AA$203,MATCH(J$11,'DEMAND BY DATE'!$A$4:$A$203,0),MATCH($C17,'DEMAND BY DATE'!$B$3:$AA$3,0)),"")) -> -1 | K17: =IF(K$11="","",IFERROR($D17-INDEX('DEMAND BY DATE'!$B$4:$AA$203,MATCH(K$11,'DEMAND BY DATE'!$A$4:$A$203,0),MATCH($C17,'DEMAND BY DATE'!$B$3:$AA$3,0)),"")) -> -1 | L17: =IF(L$11="","",IFERROR($D17-INDEX('DEMAND BY DATE'!$B$4:$AA$203,MATCH(L$11,'DEMAND BY DATE'!$A$4:$A$203,0),MATCH($C17,'DEMAND BY DATE'!$B$3:$AA$3,0)),"")) -> -1 | ... AI17: =IF(AI$11="","",IFERROR($D17-INDEX('DEMAND BY DATE'!$B$4:$AA$203,MATCH(AI$11,'DEMAND BY DATE'!$A$4:$A$203,0),MATCH($C17,'DEMAND BY DATE'!$B$3:$AA$3,0)),"")) -> 0 | BD17: =INDEX('MC MASTER'!$B$3:$B$28,12) -> F/L (Coverseam ) | BE17: =IFERROR(INDEX('MC MAP'!$BX$5:$BX$30,MATCH($BD17,'MC MAP'!$BW$5:$BW$30,0)),"?") -> FLAT-LOCK | BF17: =INDEX('MC MASTER'!$C$3:$C$28,12) -> 6 | BG17: =MAX(OFFSET('DEMAND BY DATE'!$B$4,$BB$2-1,MATCH($BD17,'DEMAND BY DATE'!$B$3:$AA$3,0)-1,$BB$3,1)) -> 17 | BH17: =$BF17-$BG17 -> -11 | BI17: {=SUMPRODUCT((OFFSET('DEMAND BY DATE'!$B$4,$BB$2-1,MATCH($BD17,'DEMAND BY DATE'!$B$3:$AA$3,0)-1,$BB$3,1)>$BF17)*(OFFSET('DEMAND BY DATE'!$BS$4,$BB$2-1,0,$BB$3,1)="Y"))} -> 26 | BJ17: {=SUMPRODUCT(($BE$6:$BE$31=$BE17)*($BH$6:$BH$31>0)*$BH$6:$BH$31)-MAX(0,$BH17)} -> 13.5 | BK17: =IF($BH17<0,MIN(-$BH17,MAX(0,$BJ17-$BN17)),0) -> 11 | BL17: =IF($BH17<0,-$BH17-$BK17,0) -> 0 | BM17: =$BH17+ROW()/100000 -> -10.99983 | BN17: {=SUMPRODUCT(($BE$6:$BE$31=$BE17)*($BH$6:$BH$31<0)*($BM$6:$BM$31<$BM17)*(-$BH$6:$BH$31))} -> 0 | BO17: =MAX(0,$BH17)-ROW()/100000 -> -0.00017
B18: =IFERROR(INDEX(WORKINGS!$B$116:$B$141,MATCH($C18,WORKINGS!$A$116:$A$141,0)),"") -> OVER-LOCK | C18: =INDEX(WORKINGS!$A$116:$A$141,MATCH(SMALL(WORKINGS!$D$116:$D$141,7),WORKINGS!$D$116:$D$141,0)) -> 5th Overlock | D18: =IFERROR(INDEX($BF$6:$BF$31,MATCH($C18,$BD$6:$BD$31,0)),0) -> 5 | E18: =IF(E$11="","",IFERROR($D18-INDEX('DEMAND BY DATE'!$B$4:$AA$203,MATCH(E$11,'DEMAND BY DATE'!$A$4:$A$203,0),MATCH($C18,'DEMAND BY DATE'!$B$3:$AA$3,0)),"")) -> 5 | F18: =IF(F$11="","",IFERROR($D18-INDEX('DEMAND BY DATE'!$B$4:$AA$203,MATCH(F$11,'DEMAND BY DATE'!$A$4:$A$203,0),MATCH($C18,'DEMAND BY DATE'!$B$3:$AA$3,0)),"")) -> 5 | G18: =IF(G$11="","",IFERROR($D18-INDEX('DEMAND BY DATE'!$B$4:$AA$203,MATCH(G$11,'DEMAND BY DATE'!$A$4:$A$203,0),MATCH($C18,'DEMAND BY DATE'!$B$3:$AA$3,0)),"")) -> 5 | H18: =IF(H$11="","",IFERROR($D18-INDEX('DEMAND BY DATE'!$B$4:$AA$203,MATCH(H$11,'DEMAND BY DATE'!$A$4:$A$203,0),MATCH($C18,'DEMAND BY DATE'!$B$3:$AA$3,0)),"")) -> 5 | I18: =IF(I$11="","",IFERROR($D18-INDEX('DEMAND BY DATE'!$B$4:$AA$203,MATCH(I$11,'DEMAND BY DATE'!$A$4:$A$203,0),MATCH($C18,'DEMAND BY DATE'!$B$3:$AA$3,0)),"")) -> 5 | J18: =IF(J$11="","",IFERROR($D18-INDEX('DEMAND BY DATE'!$B$4:$AA$203,MATCH(J$11,'DEMAND BY DATE'!$A$4:$A$203,0),MATCH($C18,'DEMAND BY DATE'!$B$3:$AA$3,0)),"")) -> 5 | K18: =IF(K$11="","",IFERROR($D18-INDEX('DEMAND BY DATE'!$B$4:$AA$203,MATCH(K$11,'DEMAND BY DATE'!$A$4:$A$203,0),MATCH($C18,'DEMAND BY DATE'!$B$3:$AA$3,0)),"")) -> 5 | L18: =IF(L$11="","",IFERROR($D18-INDEX('DEMAND BY DATE'!$B$4:$AA$203,MATCH(L$11,'DEMAND BY DATE'!$A$4:$A$203,0),MATCH($C18,'DEMAND BY DATE'!$B$3:$AA$3,0)),"")) -> 5 | ... AI18: =IF(AI$11="","",IFERROR($D18-INDEX('DEMAND BY DATE'!$B$4:$AA$203,MATCH(AI$11,'DEMAND BY DATE'!$A$4:$A$203,0),MATCH($C18,'DEMAND BY DATE'!$B$3:$AA$3,0)),"")) -> 5 | BD18: =INDEX('MC MASTER'!$B$3:$B$28,13) -> Flatlock (Ring Elastic Attach) | BE18: =IFERROR(INDEX('MC MAP'!$BX$5:$BX$30,MATCH($BD18,'MC MAP'!$BW$5:$BW$30,0)),"?") -> OUTER ELASTIC | BF18: =INDEX('MC MASTER'!$C$3:$C$28,13) -> 42 | BG18: =MAX(OFFSET('DEMAND BY DATE'!$B$4,$BB$2-1,MATCH($BD18,'DEMAND BY DATE'!$B$3:$AA$3,0)-1,$BB$3,1)) -> 34.5 | BH18: =$BF18-$BG18 -> 7.5 | BI18: {=SUMPRODUCT((OFFSET('DEMAND BY DATE'!$B$4,$BB$2-1,MATCH($BD18,'DEMAND BY DATE'!$B$3:$AA$3,0)-1,$BB$3,1)>$BF18)*(OFFSET('DEMAND BY DATE'!$BS$4,$BB$2-1,0,$BB$3,1)="Y"))} -> 0 | BJ18: {=SUMPRODUCT(($BE$6:$BE$31=$BE18)*($BH$6:$BH$31>0)*$BH$6:$BH$31)-MAX(0,$BH18)} -> 0 | BK18: =IF($BH18<0,MIN(-$BH18,MAX(0,$BJ18-$BN18)),0) -> 0 | BL18: =IF($BH18<0,-$BH18-$BK18,0) -> 0 | BM18: =$BH18+ROW()/100000 -> 7.50018 | BN18: {=SUMPRODUCT(($BE$6:$BE$31=$BE18)*($BH$6:$BH$31<0)*($BM$6:$BM$31<$BM18)*(-$BH$6:$BH$31))} -> 0 | BO18: =MAX(0,$BH18)-ROW()/100000 -> 7.49982
B19: =IFERROR(INDEX(WORKINGS!$B$116:$B$141,MATCH($C19,WORKINGS!$A$116:$A$141,0)),"") -> OVER-LOCK | C19: =INDEX(WORKINGS!$A$116:$A$141,MATCH(SMALL(WORKINGS!$D$116:$D$141,8),WORKINGS!$D$116:$D$141,0)) -> Overlock (Ring Elastic Attach) | D19: =IFERROR(INDEX($BF$6:$BF$31,MATCH($C19,$BD$6:$BD$31,0)),0) -> 29 | E19: =IF(E$11="","",IFERROR($D19-INDEX('DEMAND BY DATE'!$B$4:$AA$203,MATCH(E$11,'DEMAND BY DATE'!$A$4:$A$203,0),MATCH($C19,'DEMAND BY DATE'!$B$3:$AA$3,0)),"")) -> -7 | F19: =IF(F$11="","",IFERROR($D19-INDEX('DEMAND BY DATE'!$B$4:$AA$203,MATCH(F$11,'DEMAND BY DATE'!$A$4:$A$203,0),MATCH($C19,'DEMAND BY DATE'!$B$3:$AA$3,0)),"")) -> -7 | G19: =IF(G$11="","",IFERROR($D19-INDEX('DEMAND BY DATE'!$B$4:$AA$203,MATCH(G$11,'DEMAND BY DATE'!$A$4:$A$203,0),MATCH($C19,'DEMAND BY DATE'!$B$3:$AA$3,0)),"")) -> -7 | H19: =IF(H$11="","",IFERROR($D19-INDEX('DEMAND BY DATE'!$B$4:$AA$203,MATCH(H$11,'DEMAND BY DATE'!$A$4:$A$203,0),MATCH($C19,'DEMAND BY DATE'!$B$3:$AA$3,0)),"")) -> -7 | I19: =IF(I$11="","",IFERROR($D19-INDEX('DEMAND BY DATE'!$B$4:$AA$203,MATCH(I$11,'DEMAND BY DATE'!$A$4:$A$203,0),MATCH($C19,'DEMAND BY DATE'!$B$3:$AA$3,0)),"")) -> -7 | J19: =IF(J$11="","",IFERROR($D19-INDEX('DEMAND BY DATE'!$B$4:$AA$203,MATCH(J$11,'DEMAND BY DATE'!$A$4:$A$203,0),MATCH($C19,'DEMAND BY DATE'!$B$3:$AA$3,0)),"")) -> -7 | K19: =IF(K$11="","",IFERROR($D19-INDEX('DEMAND BY DATE'!$B$4:$AA$203,MATCH(K$11,'DEMAND BY DATE'!$A$4:$A$203,0),MATCH($C19,'DEMAND BY DATE'!$B$3:$AA$3,0)),"")) -> -7 | L19: =IF(L$11="","",IFERROR($D19-INDEX('DEMAND BY DATE'!$B$4:$AA$203,MATCH(L$11,'DEMAND BY DATE'!$A$4:$A$203,0),MATCH($C19,'DEMAND BY DATE'!$B$3:$AA$3,0)),"")) -> -7 | ... AI19: =IF(AI$11="","",IFERROR($D19-INDEX('DEMAND BY DATE'!$B$4:$AA$203,MATCH(AI$11,'DEMAND BY DATE'!$A$4:$A$203,0),MATCH($C19,'DEMAND BY DATE'!$B$3:$AA$3,0)),"")) -> -7 | BD19: =INDEX('MC MASTER'!$B$3:$B$28,14) -> 3N5T-F/L -BINDING | BE19: =IFERROR(INDEX('MC MAP'!$BX$5:$BX$30,MATCH($BD19,'MC MAP'!$BW$5:$BW$30,0)),"?") -> BINDING | BF19: =INDEX('MC MASTER'!$C$3:$C$28,14) -> 58 | BG19: =MAX(OFFSET('DEMAND BY DATE'!$B$4,$BB$2-1,MATCH($BD19,'DEMAND BY DATE'!$B$3:$AA$3,0)-1,$BB$3,1)) -> 42 | BH19: =$BF19-$BG19 -> 16 | BI19: {=SUMPRODUCT((OFFSET('DEMAND BY DATE'!$B$4,$BB$2-1,MATCH($BD19,'DEMAND BY DATE'!$B$3:$AA$3,0)-1,$BB$3,1)>$BF19)*(OFFSET('DEMAND BY DATE'!$BS$4,$BB$2-1,0,$BB$3,1)="Y"))} -> 0 | BJ19: {=SUMPRODUCT(($BE$6:$BE$31=$BE19)*($BH$6:$BH$31>0)*$BH$6:$BH$31)-MAX(0,$BH19)} -> 0 | BK19: =IF($BH19<0,MIN(-$BH19,MAX(0,$BJ19-$BN19)),0) -> 0 | BL19: =IF($BH19<0,-$BH19-$BK19,0) -> 0 | BM19: =$BH19+ROW()/100000 -> 16.00019 | BN19: {=SUMPRODUCT(($BE$6:$BE$31=$BE19)*($BH$6:$BH$31<0)*($BM$6:$BM$31<$BM19)*(-$BH$6:$BH$31))} -> 0 | BO19: =MAX(0,$BH19)-ROW()/100000 -> 15.99981
B20: =IFERROR(INDEX(WORKINGS!$B$116:$B$141,MATCH($C20,WORKINGS!$A$116:$A$141,0)),"") -> FLAT-LOCK | C20: =INDEX(WORKINGS!$A$116:$A$141,MATCH(SMALL(WORKINGS!$D$116:$D$141,9),WORKINGS!$D$116:$D$141,0)) -> Flatlock Hem | D20: =IFERROR(INDEX($BF$6:$BF$31,MATCH($C20,$BD$6:$BD$31,0)),0) -> 34 | E20: =IF(E$11="","",IFERROR($D20-INDEX('DEMAND BY DATE'!$B$4:$AA$203,MATCH(E$11,'DEMAND BY DATE'!$A$4:$A$203,0),MATCH($C20,'DEMAND BY DATE'!$B$3:$AA$3,0)),"")) -> 11.5 | F20: =IF(F$11="","",IFERROR($D20-INDEX('DEMAND BY DATE'!$B$4:$AA$203,MATCH(F$11,'DEMAND BY DATE'!$A$4:$A$203,0),MATCH($C20,'DEMAND BY DATE'!$B$3:$AA$3,0)),"")) -> 11.5 | G20: =IF(G$11="","",IFERROR($D20-INDEX('DEMAND BY DATE'!$B$4:$AA$203,MATCH(G$11,'DEMAND BY DATE'!$A$4:$A$203,0),MATCH($C20,'DEMAND BY DATE'!$B$3:$AA$3,0)),"")) -> 11.5 | H20: =IF(H$11="","",IFERROR($D20-INDEX('DEMAND BY DATE'!$B$4:$AA$203,MATCH(H$11,'DEMAND BY DATE'!$A$4:$A$203,0),MATCH($C20,'DEMAND BY DATE'!$B$3:$AA$3,0)),"")) -> 11.5 | I20: =IF(I$11="","",IFERROR($D20-INDEX('DEMAND BY DATE'!$B$4:$AA$203,MATCH(I$11,'DEMAND BY DATE'!$A$4:$A$203,0),MATCH($C20,'DEMAND BY DATE'!$B$3:$AA$3,0)),"")) -> 11.5 | J20: =IF(J$11="","",IFERROR($D20-INDEX('DEMAND BY DATE'!$B$4:$AA$203,MATCH(J$11,'DEMAND BY DATE'!$A$4:$A$203,0),MATCH($C20,'DEMAND BY DATE'!$B$3:$AA$3,0)),"")) -> 11.5 | K20: =IF(K$11="","",IFERROR($D20-INDEX('DEMAND BY DATE'!$B$4:$AA$203,MATCH(K$11,'DEMAND BY DATE'!$A$4:$A$203,0),MATCH($C20,'DEMAND BY DATE'!$B$3:$AA$3,0)),"")) -> 11.5 | L20: =IF(L$11="","",IFERROR($D20-INDEX('DEMAND BY DATE'!$B$4:$AA$203,MATCH(L$11,'DEMAND BY DATE'!$A$4:$A$203,0),MATCH($C20,'DEMAND BY DATE'!$B$3:$AA$3,0)),"")) -> 11.5 | ... AI20: =IF(AI$11="","",IFERROR($D20-INDEX('DEMAND BY DATE'!$B$4:$AA$203,MATCH(AI$11,'DEMAND BY DATE'!$A$4:$A$203,0),MATCH($C20,'DEMAND BY DATE'!$B$3:$AA$3,0)),"")) -> 6.5 | BD20: =INDEX('MC MASTER'!$B$3:$B$28,15) -> 3N5T-F/L -( TopStitch) | BE20: =IFERROR(INDEX('MC MAP'!$BX$5:$BX$30,MATCH($BD20,'MC MAP'!$BW$5:$BW$30,0)),"?") -> FLAT-LOCK | BF20: =INDEX('MC MASTER'!$C$3:$C$28,15) -> 54 | BG20: =MAX(OFFSET('DEMAND BY DATE'!$B$4,$BB$2-1,MATCH($BD20,'DEMAND BY DATE'!$B$3:$AA$3,0)-1,$BB$3,1)) -> 63 | BH20: =$BF20-$BG20 -> -9 | BI20: {=SUMPRODUCT((OFFSET('DEMAND BY DATE'!$B$4,$BB$2-1,MATCH($BD20,'DEMAND BY DATE'!$B$3:$AA$3,0)-1,$BB$3,1)>$BF20)*(OFFSET('DEMAND BY DATE'!$BS$4,$BB$2-1,0,$BB$3,1)="Y"))} -> 14 | BJ20: {=SUMPRODUCT(($BE$6:$BE$31=$BE20)*($BH$6:$BH$31>0)*$BH$6:$BH$31)-MAX(0,$BH20)} -> 13.5 | BK20: =IF($BH20<0,MIN(-$BH20,MAX(0,$BJ20-$BN20)),0) -> 2.5 | BL20: =IF($BH20<0,-$BH20-$BK20,0) -> 6.5 | BM20: =$BH20+ROW()/100000 -> -8.9998 | BN20: {=SUMPRODUCT(($BE$6:$BE$31=$BE20)*($BH$6:$BH$31<0)*($BM$6:$BM$31<$BM20)*(-$BH$6:$BH$31))} -> 11 | BO20: =MAX(0,$BH20)-ROW()/100000 -> -0.0002
B21: =IFERROR(INDEX(WORKINGS!$B$116:$B$141,MATCH($C21,WORKINGS!$A$116:$A$141,0)),"") -> FLAT-LOCK | C21: =INDEX(WORKINGS!$A$116:$A$141,MATCH(SMALL(WORKINGS!$D$116:$D$141,10),WORKINGS!$D$116:$D$141,0)) -> F/L (Coverseam / Waist COVER SEAM | D21: =IFERROR(INDEX($BF$6:$BF$31,MATCH($C21,$BD$6:$BD$31,0)),0) -> 13 | E21: =IF(E$11="","",IFERROR($D21-INDEX('DEMAND BY DATE'!$B$4:$AA$203,MATCH(E$11,'DEMAND BY DATE'!$A$4:$A$203,0),MATCH($C21,'DEMAND BY DATE'!$B$3:$AA$3,0)),"")) -> 9 | F21: =IF(F$11="","",IFERROR($D21-INDEX('DEMAND BY DATE'!$B$4:$AA$203,MATCH(F$11,'DEMAND BY DATE'!$A$4:$A$203,0),MATCH($C21,'DEMAND BY DATE'!$B$3:$AA$3,0)),"")) -> 9 | G21: =IF(G$11="","",IFERROR($D21-INDEX('DEMAND BY DATE'!$B$4:$AA$203,MATCH(G$11,'DEMAND BY DATE'!$A$4:$A$203,0),MATCH($C21,'DEMAND BY DATE'!$B$3:$AA$3,0)),"")) -> 9 | H21: =IF(H$11="","",IFERROR($D21-INDEX('DEMAND BY DATE'!$B$4:$AA$203,MATCH(H$11,'DEMAND BY DATE'!$A$4:$A$203,0),MATCH($C21,'DEMAND BY DATE'!$B$3:$AA$3,0)),"")) -> 9 | I21: =IF(I$11="","",IFERROR($D21-INDEX('DEMAND BY DATE'!$B$4:$AA$203,MATCH(I$11,'DEMAND BY DATE'!$A$4:$A$203,0),MATCH($C21,'DEMAND BY DATE'!$B$3:$AA$3,0)),"")) -> 9 | J21: =IF(J$11="","",IFERROR($D21-INDEX('DEMAND BY DATE'!$B$4:$AA$203,MATCH(J$11,'DEMAND BY DATE'!$A$4:$A$203,0),MATCH($C21,'DEMAND BY DATE'!$B$3:$AA$3,0)),"")) -> 9 | K21: =IF(K$11="","",IFERROR($D21-INDEX('DEMAND BY DATE'!$B$4:$AA$203,MATCH(K$11,'DEMAND BY DATE'!$A$4:$A$203,0),MATCH($C21,'DEMAND BY DATE'!$B$3:$AA$3,0)),"")) -> 9 | L21: =IF(L$11="","",IFERROR($D21-INDEX('DEMAND BY DATE'!$B$4:$AA$203,MATCH(L$11,'DEMAND BY DATE'!$A$4:$A$203,0),MATCH($C21,'DEMAND BY DATE'!$B$3:$AA$3,0)),"")) -> 9 | ... AI21: =IF(AI$11="","",IFERROR($D21-INDEX('DEMAND BY DATE'!$B$4:$AA$203,MATCH(AI$11,'DEMAND BY DATE'!$A$4:$A$203,0),MATCH($C21,'DEMAND BY DATE'!$B$3:$AA$3,0)),"")) -> 1 | BD21: =INDEX('MC MASTER'!$B$3:$B$28,16) -> FlatSeamer FS | BE21: =IFERROR(INDEX('MC MAP'!$BX$5:$BX$30,MATCH($BD21,'MC MAP'!$BW$5:$BW$30,0)),"?") -> FS | BF21: =INDEX('MC MASTER'!$C$3:$C$28,16) -> 8 | BG21: =MAX(OFFSET('DEMAND BY DATE'!$B$4,$BB$2-1,MATCH($BD21,'DEMAND BY DATE'!$B$3:$AA$3,0)-1,$BB$3,1)) -> 0 | BH21: =$BF21-$BG21 -> 8 | BI21: {=SUMPRODUCT((OFFSET('DEMAND BY DATE'!$B$4,$BB$2-1,MATCH($BD21,'DEMAND BY DATE'!$B$3:$AA$3,0)-1,$BB$3,1)>$BF21)*(OFFSET('DEMAND BY DATE'!$BS$4,$BB$2-1,0,$BB$3,1)="Y"))} -> 0 | BJ21: {=SUMPRODUCT(($BE$6:$BE$31=$BE21)*($BH$6:$BH$31>0)*$BH$6:$BH$31)-MAX(0,$BH21)} -> 0 | BK21: =IF($BH21<0,MIN(-$BH21,MAX(0,$BJ21-$BN21)),0) -> 0 | BL21: =IF($BH21<0,-$BH21-$BK21,0) -> 0 | BM21: =$BH21+ROW()/100000 -> 8.00021 | BN21: {=SUMPRODUCT(($BE$6:$BE$31=$BE21)*($BH$6:$BH$31<0)*($BM$6:$BM$31<$BM21)*(-$BH$6:$BH$31))} -> 0 | BO21: =MAX(0,$BH21)-ROW()/100000 -> 7.99979
B22: =IFERROR(INDEX(WORKINGS!$B$116:$B$141,MATCH($C22,WORKINGS!$A$116:$A$141,0)),"") -> FLAT-LOCK | C22: =INDEX(WORKINGS!$A$116:$A$141,MATCH(SMALL(WORKINGS!$D$116:$D$141,11),WORKINGS!$D$116:$D$141,0)) -> F/L (Coverseam )with pullar | D22: =IFERROR(INDEX($BF$6:$BF$31,MATCH($C22,$BD$6:$BD$31,0)),0) -> 37 | E22: =IF(E$11="","",IFERROR($D22-INDEX('DEMAND BY DATE'!$B$4:$AA$203,MATCH(E$11,'DEMAND BY DATE'!$A$4:$A$203,0),MATCH($C22,'DEMAND BY DATE'!$B$3:$AA$3,0)),"")) -> -6.5 | F22: =IF(F$11="","",IFERROR($D22-INDEX('DEMAND BY DATE'!$B$4:$AA$203,MATCH(F$11,'DEMAND BY DATE'!$A$4:$A$203,0),MATCH($C22,'DEMAND BY DATE'!$B$3:$AA$3,0)),"")) -> -6.5 | G22: =IF(G$11="","",IFERROR($D22-INDEX('DEMAND BY DATE'!$B$4:$AA$203,MATCH(G$11,'DEMAND BY DATE'!$A$4:$A$203,0),MATCH($C22,'DEMAND BY DATE'!$B$3:$AA$3,0)),"")) -> -6.5 | H22: =IF(H$11="","",IFERROR($D22-INDEX('DEMAND BY DATE'!$B$4:$AA$203,MATCH(H$11,'DEMAND BY DATE'!$A$4:$A$203,0),MATCH($C22,'DEMAND BY DATE'!$B$3:$AA$3,0)),"")) -> -6.5 | I22: =IF(I$11="","",IFERROR($D22-INDEX('DEMAND BY DATE'!$B$4:$AA$203,MATCH(I$11,'DEMAND BY DATE'!$A$4:$A$203,0),MATCH($C22,'DEMAND BY DATE'!$B$3:$AA$3,0)),"")) -> -6.5 | J22: =IF(J$11="","",IFERROR($D22-INDEX('DEMAND BY DATE'!$B$4:$AA$203,MATCH(J$11,'DEMAND BY DATE'!$A$4:$A$203,0),MATCH($C22,'DEMAND BY DATE'!$B$3:$AA$3,0)),"")) -> -6.5 | K22: =IF(K$11="","",IFERROR($D22-INDEX('DEMAND BY DATE'!$B$4:$AA$203,MATCH(K$11,'DEMAND BY DATE'!$A$4:$A$203,0),MATCH($C22,'DEMAND BY DATE'!$B$3:$AA$3,0)),"")) -> -6.5 | L22: =IF(L$11="","",IFERROR($D22-INDEX('DEMAND BY DATE'!$B$4:$AA$203,MATCH(L$11,'DEMAND BY DATE'!$A$4:$A$203,0),MATCH($C22,'DEMAND BY DATE'!$B$3:$AA$3,0)),"")) -> -6.5 | ... AI22: =IF(AI$11="","",IFERROR($D22-INDEX('DEMAND BY DATE'!$B$4:$AA$203,MATCH(AI$11,'DEMAND BY DATE'!$A$4:$A$203,0),MATCH($C22,'DEMAND BY DATE'!$B$3:$AA$3,0)),"")) -> -5.5 | BD22: =INDEX('MC MASTER'!$B$3:$B$28,17) -> Kansai | BE22: =IFERROR(INDEX('MC MAP'!$BX$5:$BX$30,MATCH($BD22,'MC MAP'!$BW$5:$BW$30,0)),"?") -> MULTI-NEEDLE | BF22: =INDEX('MC MASTER'!$C$3:$C$28,17) -> 8 | BG22: =MAX(OFFSET('DEMAND BY DATE'!$B$4,$BB$2-1,MATCH($BD22,'DEMAND BY DATE'!$B$3:$AA$3,0)-1,$BB$3,1)) -> 3 | BH22: =$BF22-$BG22 -> 5 | BI22: {=SUMPRODUCT((OFFSET('DEMAND BY DATE'!$B$4,$BB$2-1,MATCH($BD22,'DEMAND BY DATE'!$B$3:$AA$3,0)-1,$BB$3,1)>$BF22)*(OFFSET('DEMAND BY DATE'!$BS$4,$BB$2-1,0,$BB$3,1)="Y"))} -> 0 | BJ22: {=SUMPRODUCT(($BE$6:$BE$31=$BE22)*($BH$6:$BH$31>0)*$BH$6:$BH$31)-MAX(0,$BH22)} -> 0 | BK22: =IF($BH22<0,MIN(-$BH22,MAX(0,$BJ22-$BN22)),0) -> 0 | BL22: =IF($BH22<0,-$BH22-$BK22,0) -> 0 | BM22: =$BH22+ROW()/100000 -> 5.00022 | BN22: {=SUMPRODUCT(($BE$6:$BE$31=$BE22)*($BH$6:$BH$31<0)*($BM$6:$BM$31<$BM22)*(-$BH$6:$BH$31))} -> 0 | BO22: =MAX(0,$BH22)-ROW()/100000 -> 4.99978
B23: =IFERROR(INDEX(WORKINGS!$B$116:$B$141,MATCH($C23,WORKINGS!$A$116:$A$141,0)),"") -> FLAT-LOCK | C23: =INDEX(WORKINGS!$A$116:$A$141,MATCH(SMALL(WORKINGS!$D$116:$D$141,12),WORKINGS!$D$116:$D$141,0)) -> F/L (Coverseam ) | D23: =IFERROR(INDEX($BF$6:$BF$31,MATCH($C23,$BD$6:$BD$31,0)),0) -> 6 | E23: =IF(E$11="","",IFERROR($D23-INDEX('DEMAND BY DATE'!$B$4:$AA$203,MATCH(E$11,'DEMAND BY DATE'!$A$4:$A$203,0),MATCH($C23,'DEMAND BY DATE'!$B$3:$AA$3,0)),"")) -> -11 | F23: =IF(F$11="","",IFERROR($D23-INDEX('DEMAND BY DATE'!$B$4:$AA$203,MATCH(F$11,'DEMAND BY DATE'!$A$4:$A$203,0),MATCH($C23,'DEMAND BY DATE'!$B$3:$AA$3,0)),"")) -> -11 | G23: =IF(G$11="","",IFERROR($D23-INDEX('DEMAND BY DATE'!$B$4:$AA$203,MATCH(G$11,'DEMAND BY DATE'!$A$4:$A$203,0),MATCH($C23,'DEMAND BY DATE'!$B$3:$AA$3,0)),"")) -> -11 | H23: =IF(H$11="","",IFERROR($D23-INDEX('DEMAND BY DATE'!$B$4:$AA$203,MATCH(H$11,'DEMAND BY DATE'!$A$4:$A$203,0),MATCH($C23,'DEMAND BY DATE'!$B$3:$AA$3,0)),"")) -> -11 | I23: =IF(I$11="","",IFERROR($D23-INDEX('DEMAND BY DATE'!$B$4:$AA$203,MATCH(I$11,'DEMAND BY DATE'!$A$4:$A$203,0),MATCH($C23,'DEMAND BY DATE'!$B$3:$AA$3,0)),"")) -> -11 | J23: =IF(J$11="","",IFERROR($D23-INDEX('DEMAND BY DATE'!$B$4:$AA$203,MATCH(J$11,'DEMAND BY DATE'!$A$4:$A$203,0),MATCH($C23,'DEMAND BY DATE'!$B$3:$AA$3,0)),"")) -> -11 | K23: =IF(K$11="","",IFERROR($D23-INDEX('DEMAND BY DATE'!$B$4:$AA$203,MATCH(K$11,'DEMAND BY DATE'!$A$4:$A$203,0),MATCH($C23,'DEMAND BY DATE'!$B$3:$AA$3,0)),"")) -> -11 | L23: =IF(L$11="","",IFERROR($D23-INDEX('DEMAND BY DATE'!$B$4:$AA$203,MATCH(L$11,'DEMAND BY DATE'!$A$4:$A$203,0),MATCH($C23,'DEMAND BY DATE'!$B$3:$AA$3,0)),"")) -> -11 | ... AI23: =IF(AI$11="","",IFERROR($D23-INDEX('DEMAND BY DATE'!$B$4:$AA$203,MATCH(AI$11,'DEMAND BY DATE'!$A$4:$A$203,0),MATCH($C23,'DEMAND BY DATE'!$B$3:$AA$3,0)),"")) -> -11 | BD23: =INDEX('MC MASTER'!$B$3:$B$28,18) -> Chain stitch | BE23: =IFERROR(INDEX('MC MAP'!$BX$5:$BX$30,MATCH($BD23,'MC MAP'!$BW$5:$BW$30,0)),"?") -> CS-DNLS | BF23: =INDEX('MC MASTER'!$C$3:$C$28,18) -> 2 | BG23: =MAX(OFFSET('DEMAND BY DATE'!$B$4,$BB$2-1,MATCH($BD23,'DEMAND BY DATE'!$B$3:$AA$3,0)-1,$BB$3,1)) -> 0 | BH23: =$BF23-$BG23 -> 2 | BI23: {=SUMPRODUCT((OFFSET('DEMAND BY DATE'!$B$4,$BB$2-1,MATCH($BD23,'DEMAND BY DATE'!$B$3:$AA$3,0)-1,$BB$3,1)>$BF23)*(OFFSET('DEMAND BY DATE'!$BS$4,$BB$2-1,0,$BB$3,1)="Y"))} -> 0 | BJ23: {=SUMPRODUCT(($BE$6:$BE$31=$BE23)*($BH$6:$BH$31>0)*$BH$6:$BH$31)-MAX(0,$BH23)} -> 0 | BK23: =IF($BH23<0,MIN(-$BH23,MAX(0,$BJ23-$BN23)),0) -> 0 | BL23: =IF($BH23<0,-$BH23-$BK23,0) -> 0 | BM23: =$BH23+ROW()/100000 -> 2.00023 | BN23: {=SUMPRODUCT(($BE$6:$BE$31=$BE23)*($BH$6:$BH$31<0)*($BM$6:$BM$31<$BM23)*(-$BH$6:$BH$31))} -> 0 | BO23: =MAX(0,$BH23)-ROW()/100000 -> 1.99977
B24: =IFERROR(INDEX(WORKINGS!$B$116:$B$141,MATCH($C24,WORKINGS!$A$116:$A$141,0)),"") -> FLAT-LOCK | C24: =INDEX(WORKINGS!$A$116:$A$141,MATCH(SMALL(WORKINGS!$D$116:$D$141,13),WORKINGS!$D$116:$D$141,0)) -> 3N5T-F/L -( TopStitch) | D24: =IFERROR(INDEX($BF$6:$BF$31,MATCH($C24,$BD$6:$BD$31,0)),0) -> 54 | E24: =IF(E$11="","",IFERROR($D24-INDEX('DEMAND BY DATE'!$B$4:$AA$203,MATCH(E$11,'DEMAND BY DATE'!$A$4:$A$203,0),MATCH($C24,'DEMAND BY DATE'!$B$3:$AA$3,0)),"")) -> 7 | F24: =IF(F$11="","",IFERROR($D24-INDEX('DEMAND BY DATE'!$B$4:$AA$203,MATCH(F$11,'DEMAND BY DATE'!$A$4:$A$203,0),MATCH($C24,'DEMAND BY DATE'!$B$3:$AA$3,0)),"")) -> 7 | G24: =IF(G$11="","",IFERROR($D24-INDEX('DEMAND BY DATE'!$B$4:$AA$203,MATCH(G$11,'DEMAND BY DATE'!$A$4:$A$203,0),MATCH($C24,'DEMAND BY DATE'!$B$3:$AA$3,0)),"")) -> 7 | H24: =IF(H$11="","",IFERROR($D24-INDEX('DEMAND BY DATE'!$B$4:$AA$203,MATCH(H$11,'DEMAND BY DATE'!$A$4:$A$203,0),MATCH($C24,'DEMAND BY DATE'!$B$3:$AA$3,0)),"")) -> 7 | I24: =IF(I$11="","",IFERROR($D24-INDEX('DEMAND BY DATE'!$B$4:$AA$203,MATCH(I$11,'DEMAND BY DATE'!$A$4:$A$203,0),MATCH($C24,'DEMAND BY DATE'!$B$3:$AA$3,0)),"")) -> 7 | J24: =IF(J$11="","",IFERROR($D24-INDEX('DEMAND BY DATE'!$B$4:$AA$203,MATCH(J$11,'DEMAND BY DATE'!$A$4:$A$203,0),MATCH($C24,'DEMAND BY DATE'!$B$3:$AA$3,0)),"")) -> 7 | K24: =IF(K$11="","",IFERROR($D24-INDEX('DEMAND BY DATE'!$B$4:$AA$203,MATCH(K$11,'DEMAND BY DATE'!$A$4:$A$203,0),MATCH($C24,'DEMAND BY DATE'!$B$3:$AA$3,0)),"")) -> 7 | L24: =IF(L$11="","",IFERROR($D24-INDEX('DEMAND BY DATE'!$B$4:$AA$203,MATCH(L$11,'DEMAND BY DATE'!$A$4:$A$203,0),MATCH($C24,'DEMAND BY DATE'!$B$3:$AA$3,0)),"")) -> 7 | ... AI24: =IF(AI$11="","",IFERROR($D24-INDEX('DEMAND BY DATE'!$B$4:$AA$203,MATCH(AI$11,'DEMAND BY DATE'!$A$4:$A$203,0),MATCH($C24,'DEMAND BY DATE'!$B$3:$AA$3,0)),"")) -> -9 | BD24: =INDEX('MC MASTER'!$B$3:$B$28,19) -> Flatlock (VT) | BE24: =IFERROR(INDEX('MC MAP'!$BX$5:$BX$30,MATCH($BD24,'MC MAP'!$BW$5:$BW$30,0)),"?") -> FLAT-LOCK | BF24: =INDEX('MC MASTER'!$C$3:$C$28,19) -> 21 | BG24: =MAX(OFFSET('DEMAND BY DATE'!$B$4,$BB$2-1,MATCH($BD24,'DEMAND BY DATE'!$B$3:$AA$3,0)-1,$BB$3,1)) -> 15 | BH24: =$BF24-$BG24 -> 6 | BI24: {=SUMPRODUCT((OFFSET('DEMAND BY DATE'!$B$4,$BB$2-1,MATCH($BD24,'DEMAND BY DATE'!$B$3:$AA$3,0)-1,$BB$3,1)>$BF24)*(OFFSET('DEMAND BY DATE'!$BS$4,$BB$2-1,0,$BB$3,1)="Y"))} -> 0 | BJ24: {=SUMPRODUCT(($BE$6:$BE$31=$BE24)*($BH$6:$BH$31>0)*$BH$6:$BH$31)-MAX(0,$BH24)} -> 7.5 | BK24: =IF($BH24<0,MIN(-$BH24,MAX(0,$BJ24-$BN24)),0) -> 0 | BL24: =IF($BH24<0,-$BH24-$BK24,0) -> 0 | BM24: =$BH24+ROW()/100000 -> 6.00024 | BN24: {=SUMPRODUCT(($BE$6:$BE$31=$BE24)*($BH$6:$BH$31<0)*($BM$6:$BM$31<$BM24)*(-$BH$6:$BH$31))} -> 26.5 | BO24: =MAX(0,$BH24)-ROW()/100000 -> 5.99976
B25: =IFERROR(INDEX(WORKINGS!$B$116:$B$141,MATCH($C25,WORKINGS!$A$116:$A$141,0)),"") -> FLAT-LOCK | C25: =INDEX(WORKINGS!$A$116:$A$141,MATCH(SMALL(WORKINGS!$D$116:$D$141,14),WORKINGS!$D$116:$D$141,0)) -> Flatlock (VT) | D25: =IFERROR(INDEX($BF$6:$BF$31,MATCH($C25,$BD$6:$BD$31,0)),0) -> 21 | E25: =IF(E$11="","",IFERROR($D25-INDEX('DEMAND BY DATE'!$B$4:$AA$203,MATCH(E$11,'DEMAND BY DATE'!$A$4:$A$203,0),MATCH($C25,'DEMAND BY DATE'!$B$3:$AA$3,0)),"")) -> 8 | F25: =IF(F$11="","",IFERROR($D25-INDEX('DEMAND BY DATE'!$B$4:$AA$203,MATCH(F$11,'DEMAND BY DATE'!$A$4:$A$203,0),MATCH($C25,'DEMAND BY DATE'!$B$3:$AA$3,0)),"")) -> 8 | G25: =IF(G$11="","",IFERROR($D25-INDEX('DEMAND BY DATE'!$B$4:$AA$203,MATCH(G$11,'DEMAND BY DATE'!$A$4:$A$203,0),MATCH($C25,'DEMAND BY DATE'!$B$3:$AA$3,0)),"")) -> 8 | H25: =IF(H$11="","",IFERROR($D25-INDEX('DEMAND BY DATE'!$B$4:$AA$203,MATCH(H$11,'DEMAND BY DATE'!$A$4:$A$203,0),MATCH($C25,'DEMAND BY DATE'!$B$3:$AA$3,0)),"")) -> 8 | I25: =IF(I$11="","",IFERROR($D25-INDEX('DEMAND BY DATE'!$B$4:$AA$203,MATCH(I$11,'DEMAND BY DATE'!$A$4:$A$203,0),MATCH($C25,'DEMAND BY DATE'!$B$3:$AA$3,0)),"")) -> 8 | J25: =IF(J$11="","",IFERROR($D25-INDEX('DEMAND BY DATE'!$B$4:$AA$203,MATCH(J$11,'DEMAND BY DATE'!$A$4:$A$203,0),MATCH($C25,'DEMAND BY DATE'!$B$3:$AA$3,0)),"")) -> 8 | K25: =IF(K$11="","",IFERROR($D25-INDEX('DEMAND BY DATE'!$B$4:$AA$203,MATCH(K$11,'DEMAND BY DATE'!$A$4:$A$203,0),MATCH($C25,'DEMAND BY DATE'!$B$3:$AA$3,0)),"")) -> 8 | L25: =IF(L$11="","",IFERROR($D25-INDEX('DEMAND BY DATE'!$B$4:$AA$203,MATCH(L$11,'DEMAND BY DATE'!$A$4:$A$203,0),MATCH($C25,'DEMAND BY DATE'!$B$3:$AA$3,0)),"")) -> 8 | ... AI25: =IF(AI$11="","",IFERROR($D25-INDEX('DEMAND BY DATE'!$B$4:$AA$203,MATCH(AI$11,'DEMAND BY DATE'!$A$4:$A$203,0),MATCH($C25,'DEMAND BY DATE'!$B$3:$AA$3,0)),"")) -> 6 | BD25: =INDEX('MC MASTER'!$B$3:$B$28,20) -> Heat Seal | BE25: =IFERROR(INDEX('MC MAP'!$BX$5:$BX$30,MATCH($BD25,'MC MAP'!$BW$5:$BW$30,0)),"?") -> HT | BF25: =INDEX('MC MASTER'!$C$3:$C$28,20) -> 35 | BG25: =MAX(OFFSET('DEMAND BY DATE'!$B$4,$BB$2-1,MATCH($BD25,'DEMAND BY DATE'!$B$3:$AA$3,0)-1,$BB$3,1)) -> 32.5 | BH25: =$BF25-$BG25 -> 2.5 | BI25: {=SUMPRODUCT((OFFSET('DEMAND BY DATE'!$B$4,$BB$2-1,MATCH($BD25,'DEMAND BY DATE'!$B$3:$AA$3,0)-1,$BB$3,1)>$BF25)*(OFFSET('DEMAND BY DATE'!$BS$4,$BB$2-1,0,$BB$3,1)="Y"))} -> 0 | BJ25: {=SUMPRODUCT(($BE$6:$BE$31=$BE25)*($BH$6:$BH$31>0)*$BH$6:$BH$31)-MAX(0,$BH25)} -> 0 | BK25: =IF($BH25<0,MIN(-$BH25,MAX(0,$BJ25-$BN25)),0) -> 0 | BL25: =IF($BH25<0,-$BH25-$BK25,0) -> 0 | BM25: =$BH25+ROW()/100000 -> 2.50025 | BN25: {=SUMPRODUCT(($BE$6:$BE$31=$BE25)*($BH$6:$BH$31<0)*($BM$6:$BM$31<$BM25)*(-$BH$6:$BH$31))} -> 0 | BO25: =MAX(0,$BH25)-ROW()/100000 -> 2.49975
B26: =IFERROR(INDEX(WORKINGS!$B$116:$B$141,MATCH($C26,WORKINGS!$A$116:$A$141,0)),"") -> OUTER ELASTIC | C26: =INDEX(WORKINGS!$A$116:$A$141,MATCH(SMALL(WORKINGS!$D$116:$D$141,15),WORKINGS!$D$116:$D$141,0)) -> Flatlock (Ring Elastic Attach) | D26: =IFERROR(INDEX($BF$6:$BF$31,MATCH($C26,$BD$6:$BD$31,0)),0) -> 42 | E26: =IF(E$11="","",IFERROR($D26-INDEX('DEMAND BY DATE'!$B$4:$AA$203,MATCH(E$11,'DEMAND BY DATE'!$A$4:$A$203,0),MATCH($C26,'DEMAND BY DATE'!$B$3:$AA$3,0)),"")) -> 7.5 | F26: =IF(F$11="","",IFERROR($D26-INDEX('DEMAND BY DATE'!$B$4:$AA$203,MATCH(F$11,'DEMAND BY DATE'!$A$4:$A$203,0),MATCH($C26,'DEMAND BY DATE'!$B$3:$AA$3,0)),"")) -> 7.5 | G26: =IF(G$11="","",IFERROR($D26-INDEX('DEMAND BY DATE'!$B$4:$AA$203,MATCH(G$11,'DEMAND BY DATE'!$A$4:$A$203,0),MATCH($C26,'DEMAND BY DATE'!$B$3:$AA$3,0)),"")) -> 7.5 | H26: =IF(H$11="","",IFERROR($D26-INDEX('DEMAND BY DATE'!$B$4:$AA$203,MATCH(H$11,'DEMAND BY DATE'!$A$4:$A$203,0),MATCH($C26,'DEMAND BY DATE'!$B$3:$AA$3,0)),"")) -> 7.5 | I26: =IF(I$11="","",IFERROR($D26-INDEX('DEMAND BY DATE'!$B$4:$AA$203,MATCH(I$11,'DEMAND BY DATE'!$A$4:$A$203,0),MATCH($C26,'DEMAND BY DATE'!$B$3:$AA$3,0)),"")) -> 7.5 | J26: =IF(J$11="","",IFERROR($D26-INDEX('DEMAND BY DATE'!$B$4:$AA$203,MATCH(J$11,'DEMAND BY DATE'!$A$4:$A$203,0),MATCH($C26,'DEMAND BY DATE'!$B$3:$AA$3,0)),"")) -> 7.5 | K26: =IF(K$11="","",IFERROR($D26-INDEX('DEMAND BY DATE'!$B$4:$AA$203,MATCH(K$11,'DEMAND BY DATE'!$A$4:$A$203,0),MATCH($C26,'DEMAND BY DATE'!$B$3:$AA$3,0)),"")) -> 7.5 | L26: =IF(L$11="","",IFERROR($D26-INDEX('DEMAND BY DATE'!$B$4:$AA$203,MATCH(L$11,'DEMAND BY DATE'!$A$4:$A$203,0),MATCH($C26,'DEMAND BY DATE'!$B$3:$AA$3,0)),"")) -> 7.5 | ... AI26: =IF(AI$11="","",IFERROR($D26-INDEX('DEMAND BY DATE'!$B$4:$AA$203,MATCH(AI$11,'DEMAND BY DATE'!$A$4:$A$203,0),MATCH($C26,'DEMAND BY DATE'!$B$3:$AA$3,0)),"")) -> 13.5 | BD26: =INDEX('MC MASTER'!$B$3:$B$28,21) -> Snap button | BE26: =IFERROR(INDEX('MC MAP'!$BX$5:$BX$30,MATCH($BD26,'MC MAP'!$BW$5:$BW$30,0)),"?") -> ILET | BF26: =INDEX('MC MASTER'!$C$3:$C$28,21) -> 2 | BG26: =MAX(OFFSET('DEMAND BY DATE'!$B$4,$BB$2-1,MATCH($BD26,'DEMAND BY DATE'!$B$3:$AA$3,0)-1,$BB$3,1)) -> 2 | BH26: =$BF26-$BG26 -> 0 | BI26: {=SUMPRODUCT((OFFSET('DEMAND BY DATE'!$B$4,$BB$2-1,MATCH($BD26,'DEMAND BY DATE'!$B$3:$AA$3,0)-1,$BB$3,1)>$BF26)*(OFFSET('DEMAND BY DATE'!$BS$4,$BB$2-1,0,$BB$3,1)="Y"))} -> 0 | BJ26: {=SUMPRODUCT(($BE$6:$BE$31=$BE26)*($BH$6:$BH$31>0)*$BH$6:$BH$31)-MAX(0,$BH26)} -> 0 | BK26: =IF($BH26<0,MIN(-$BH26,MAX(0,$BJ26-$BN26)),0) -> 0 | BL26: =IF($BH26<0,-$BH26-$BK26,0) -> 0 | BM26: =$BH26+ROW()/100000 -> 0.00026 | BN26: {=SUMPRODUCT(($BE$6:$BE$31=$BE26)*($BH$6:$BH$31<0)*($BM$6:$BM$31<$BM26)*(-$BH$6:$BH$31))} -> 0 | BO26: =MAX(0,$BH26)-ROW()/100000 -> -0.00026
