Workbook

Sheet Master
B1: PPC Production Planning Template | U1: ACTUALS — enter after shipment | Y1: NOTES
B2: Month | C2: Seq | D2: Style | E2: PO | F2: ODR. Qty | G2: Produce Till Date | H2: Balance | I2: Dely Date | J2: Ex-Factory | K2: Lines | L2: Production/LINE | M2: Days Req | N2: Manual Start | O2: Start Date | P2: End Date | Q2: Projected Ex-Fac | R2: Def | S2: Fabric/Trims I/H Date | T2: OTIF (Projected) | U2: Actual Ex-Fac | V2: Shipped Qty | W2: OTIF (Actual) | Y2: Blue cells are inputs; grey cells are formulas.
B3: M5 | C3: 1 | D3: 4300 | E3: 7111632906 | F3: 2678 | G3: 2678 | H3: =IF(OR(D3="",E3=""),"",IFERROR(F3-G3,"-")) -> 0 | I3: 46239 | J3: =IF(I3="","",IFERROR(WORKDAY.INTL(I3,-10,"0000001",Holidays!$A$6:$A$55),"-")) -> 46227 | M3: =IF(OR(D3="",E3="",F3="",K3="",L3=""),"",IFERROR(ROUNDUP(H3/(K3*L3),0),"-")) | N3: Close | O3: {=IF(OR($D3="",$E3=""),"",IF($N3<>"",$N3,IFERROR(WORKDAY.INTL(LOOKUP(2,1/(($D$2:D2=$D3)*ISNUMBER($P$2:P2)),$P$2:P2),1,"0000001",Holidays!$A$6:$A$55),"")))} -> Close | P3: =IF(OR(O3="",H3="",K3="",L3=""),"",IFERROR(WORKDAY.INTL(O3-1,MAX(1,ROUNDUP(H3/(K3*L3),0)),"0000001",Holidays!$A$6:$A$55),"-")) | Q3: =IF(P3="","",IFERROR(WORKDAY.INTL(P3,3,"0000001",Holidays!$A$6:$A$55),"-")) | R3: =IF(OR(J3="",P3=""),"",IFERROR(NETWORKDAYS.INTL(P3+1,J3,"0000001",Holidays!$A$6:$A$55),"-")) | S3: =IF(O3="","",IFERROR(WORKDAY.INTL(O3,-10,"0000001",Holidays!$A$6:$A$55),"-")) -> - | T3: =IF(OR(I3="",Q3=""),"",IF(Q3<=I3-4,1,0)) | W3: =IF(OR($U3="",$V3="",$I3=""),"",IF(AND($U3<=$I3-4,$V3>=$F3),1,0)) | Y3: Start Date: Manual Start wins. Otherwise the order starts 1 working day after the last planned end date of the same style above it.
B4: M5 | C4: 2 | D4: 4300 | E4: 7207749635 | F4: 2950 | G4: 0 | H4: =IF(OR(D4="",E4=""),"",IFERROR(F4-G4,"-")) -> 2950 | I4: 46239 | J4: =IF(I4="","",IFERROR(WORKDAY.INTL(I4,-10,"0000001",Holidays!$A$6:$A$55),"-")) -> 46227 | K4: 1 | L4: 850 | M4: =IF(OR(D4="",E4="",F4="",K4="",L4=""),"",IFERROR(ROUNDUP(H4/(K4*L4),0),"-")) -> 4 | N4: 46258 | O4: {=IF(OR($D4="",$E4=""),"",IF($N4<>"",$N4,IFERROR(WORKDAY.INTL(LOOKUP(2,1/(($D$2:D3=$D4)*ISNUMBER($P$2:P3)),$P$2:P3),1,"0000001",Holidays!$A$6:$A$55),"")))} -> 46258 | P4: =IF(OR(O4="",H4="",K4="",L4=""),"",IFERROR(WORKDAY.INTL(O4-1,MAX(1,ROUNDUP(H4/(K4*L4),0)),"0000001",Holidays!$A$6:$A$55),"-")) -> 46261 | Q4: =IF(P4="","",IFERROR(WORKDAY.INTL(P4,3,"0000001",Holidays!$A$6:$A$55),"-")) -> 46266 | R4: =IF(OR(J4="",P4=""),"",IFERROR(NETWORKDAYS.INTL(P4+1,J4,"0000001",Holidays!$A$6:$A$55),"-")) -> -29 | S4: =IF(O4="","",IFERROR(WORKDAY.INTL(O4,-10,"0000001",Holidays!$A$6:$A$55),"-")) -> 46245 | T4: =IF(OR(I4="",Q4=""),"",IF(Q4<=I4-4,1,0)) -> 0 | W4: =IF(OR($U4="",$V4="",$I4=""),"",IF(AND($U4<=$I4-4,$V4>=$F4),1,0)) | Y4: Type "Close" in Manual Start for an order that is finished or not to be scheduled.
B5: M6 | C5: 3 | D5: 4300 | E5: 7837962265 | F5: 2580 | G5: 0 | H5: =IF(OR(D5="",E5=""),"",IFERROR(F5-G5,"-")) -> 2580 | I5: 46262 | J5: =IF(I5="","",IFERROR(WORKDAY.INTL(I5,-10,"0000001",Holidays!$A$6:$A$55),"-")) -> 46251 | K5: 1 | L5: 850 | M5: =IF(OR(D5="",E5="",F5="",K5="",L5=""),"",IFERROR(ROUNDUP(H5/(K5*L5),0),"-")) -> 4 | N5: 46262 | O5: {=IF(OR($D5="",$E5=""),"",IF($N5<>"",$N5,IFERROR(WORKDAY.INTL(LOOKUP(2,1/(($D$2:D4=$D5)*ISNUMBER($P$2:P4)),$P$2:P4),1,"0000001",Holidays!$A$6:$A$55),"")))} -> 46262 | P5: =IF(OR(O5="",H5="",K5="",L5=""),"",IFERROR(WORKDAY.INTL(O5-1,MAX(1,ROUNDUP(H5/(K5*L5),0)),"0000001",Holidays!$A$6:$A$55),"-")) -> 46267 | Q5: =IF(P5="","",IFERROR(WORKDAY.INTL(P5,3,"0000001",Holidays!$A$6:$A$55),"-")) -> 46270 | R5: =IF(OR(J5="",P5=""),"",IFERROR(NETWORKDAYS.INTL(P5+1,J5,"0000001",Holidays!$A$6:$A$55),"-")) -> -15 | S5: =IF(O5="","",IFERROR(WORKDAY.INTL(O5,-10,"0000001",Holidays!$A$6:$A$55),"-")) -> 46251 | T5: =IF(OR(I5="",Q5=""),"",IF(Q5<=I5-4,1,0)) -> 0 | W5: =IF(OR($U5="",$V5="",$I5=""),"",IF(AND($U5<=$I5-4,$V5>=$F5),1,0)) | Y5: Planned Ex-Factory = Delivery date − 10 working days. Fabric/Trims in-house = Start − 10 working days.
B6: M8 | C6: 4 | D6: 4300 | E6: 7406530527 | F6: 731 | G6: 0 | H6: =IF(OR(D6="",E6=""),"",IFERROR(F6-G6,"-")) -> 731 | I6: 46332 | J6: =IF(I6="","",IFERROR(WORKDAY.INTL(I6,-10,"0000001",Holidays!$A$6:$A$55),"-")) -> 46321 | K6: 1 | L6: 850 | M6: =IF(OR(D6="",E6="",F6="",K6="",L6=""),"",IFERROR(ROUNDUP(H6/(K6*L6),0),"-")) -> 1 | N6: 46314 | O6: {=IF(OR($D6="",$E6=""),"",IF($N6<>"",$N6,IFERROR(WORKDAY.INTL(LOOKUP(2,1/(($D$2:D5=$D6)*ISNUMBER($P$2:P5)),$P$2:P5),1,"0000001",Holidays!$A$6:$A$55),"")))} -> 46314 | P6: =IF(OR(O6="",H6="",K6="",L6=""),"",IFERROR(WORKDAY.INTL(O6-1,MAX(1,ROUNDUP(H6/(K6*L6),0)),"0000001",Holidays!$A$6:$A$55),"-")) -> 46314 | Q6: =IF(P6="","",IFERROR(WORKDAY.INTL(P6,3,"0000001",Holidays!$A$6:$A$55),"-")) -> 46318 | R6: =IF(OR(J6="",P6=""),"",IFERROR(NETWORKDAYS.INTL(P6+1,J6,"0000001",Holidays!$A$6:$A$55),"-")) -> 5 | S6: =IF(O6="","",IFERROR(WORKDAY.INTL(O6,-10,"0000001",Holidays!$A$6:$A$55),"-")) -> 46302 | T6: =IF(OR(I6="",Q6=""),"",IF(Q6<=I6-4,1,0)) -> 1 | W6: =IF(OR($U6="",$V6="",$I6=""),"",IF(AND($U6<=$I6-4,$V6>=$F6),1,0)) | Y6: Projected Ex-Fac = End date + 3 working days. Def = working days of buffer between End date and Planned Ex-Factory (negative = late).
B7: M9 | C7: 5 | D7: 4300 | E7: 7601081513 | F7: 1194 | G7: 0 | H7: =IF(OR(D7="",E7=""),"",IFERROR(F7-G7,"-")) -> 1194 | I7: 46360 | J7: =IF(I7="","",IFERROR(WORKDAY.INTL(I7,-10,"0000001",Holidays!$A$6:$A$55),"-")) -> 46349 | K7: 1 | L7: 850 | M7: =IF(OR(D7="",E7="",F7="",K7="",L7=""),"",IFERROR(ROUNDUP(H7/(K7*L7),0),"-")) -> 2 | O7: {=IF(OR($D7="",$E7=""),"",IF($N7<>"",$N7,IFERROR(WORKDAY.INTL(LOOKUP(2,1/(($D$2:D6=$D7)*ISNUMBER($P$2:P6)),$P$2:P6),1,"0000001",Holidays!$A$6:$A$55),"")))} -> 46316 | P7: =IF(OR(O7="",H7="",K7="",L7=""),"",IFERROR(WORKDAY.INTL(O7-1,MAX(1,ROUNDUP(H7/(K7*L7),0)),"0000001",Holidays!$A$6:$A$55),"-")) -> 46317 | Q7: =IF(P7="","",IFERROR(WORKDAY.INTL(P7,3,"0000001",Holidays!$A$6:$A$55),"-")) -> 46321 | R7: =IF(OR(J7="",P7=""),"",IFERROR(NETWORKDAYS.INTL(P7+1,J7,"0000001",Holidays!$A$6:$A$55),"-")) -> 25 | S7: =IF(O7="","",IFERROR(WORKDAY.INTL(O7,-10,"0000001",Holidays!$A$6:$A$55),"-")) -> 46303 | T7: =IF(OR(I7="",Q7=""),"",IF(Q7<=I7-4,1,0)) -> 1 | W7: =IF(OR($U7="",$V7="",$I7=""),"",IF(AND($U7<=$I7-4,$V7>=$F7),1,0)) | Y7: OTIF (Projected) = 1 if Projected Ex-Fac is at least 4 days before the delivery date. It is a forecast, not a result.
B8: M5 | C8: 1 | D8: 4301 | E8: 7040935107 | F8: 4144 | G8: 4144 | H8: =IF(OR(D8="",E8=""),"",IFERROR(F8-G8,"-")) -> 0 | I8: 46239 | J8: =IF(I8="","",IFERROR(WORKDAY.INTL(I8,-10,"0000001",Holidays!$A$6:$A$55),"-")) -> 46227 | M8: =IF(OR(D8="",E8="",F8="",K8="",L8=""),"",IFERROR(ROUNDUP(H8/(K8*L8),0),"-")) | N8: Close | O8: {=IF(OR($D8="",$E8=""),"",IF($N8<>"",$N8,IFERROR(WORKDAY.INTL(LOOKUP(2,1/(($D$2:D7=$D8)*ISNUMBER($P$2:P7)),$P$2:P7),1,"0000001",Holidays!$A$6:$A$55),"")))} -> Close | P8: =IF(OR(O8="",H8="",K8="",L8=""),"",IFERROR(WORKDAY.INTL(O8-1,MAX(1,ROUNDUP(H8/(K8*L8),0)),"0000001",Holidays!$A$6:$A$55),"-")) | Q8: =IF(P8="","",IFERROR(WORKDAY.INTL(P8,3,"0000001",Holidays!$A$6:$A$55),"-")) | R8: =IF(OR(J8="",P8=""),"",IFERROR(NETWORKDAYS.INTL(P8+1,J8,"0000001",Holidays!$A$6:$A$55),"-")) | S8: =IF(O8="","",IFERROR(WORKDAY.INTL(O8,-10,"0000001",Holidays!$A$6:$A$55),"-")) -> - | T8: =IF(OR(I8="",Q8=""),"",IF(Q8<=I8-4,1,0)) | W8: =IF(OR($U8="",$V8="",$I8=""),"",IF(AND($U8<=$I8-4,$V8>=$F8),1,0)) | Y8: OTIF (Actual) = 1 only when the Actual Ex-Fac is at least 4 days before delivery AND Shipped Qty ≥ Order Qty.
B9: M5 | C9: 2 | D9: 4301 | E9: 7711945303 | F9: 1190 | G9: 1190 | H9: =IF(OR(D9="",E9=""),"",IFERROR(F9-G9,"-")) -> 0 | I9: 46248 | J9: =IF(I9="","",IFERROR(WORKDAY.INTL(I9,-10,"0000001",Holidays!$A$6:$A$55),"-")) -> 46237 | M9: =IF(OR(D9="",E9="",F9="",K9="",L9=""),"",IFERROR(ROUNDUP(H9/(K9*L9),0),"-")) | N9: Close | O9: {=IF(OR($D9="",$E9=""),"",IF($N9<>"",$N9,IFERROR(WORKDAY.INTL(LOOKUP(2,1/(($D$2:D8=$D9)*ISNUMBER($P$2:P8)),$P$2:P8),1,"0000001",Holidays!$A$6:$A$55),"")))} -> Close | P9: =IF(OR(O9="",H9="",K9="",L9=""),"",IFERROR(WORKDAY.INTL(O9-1,MAX(1,ROUNDUP(H9/(K9*L9),0)),"0000001",Holidays!$A$6:$A$55),"-")) | Q9: =IF(P9="","",IFERROR(WORKDAY.INTL(P9,3,"0000001",Holidays!$A$6:$A$55),"-")) | R9: =IF(OR(J9="",P9=""),"",IFERROR(NETWORKDAYS.INTL(P9+1,J9,"0000001",Holidays!$A$6:$A$55),"-")) | S9: =IF(O9="","",IFERROR(WORKDAY.INTL(O9,-10,"0000001",Holidays!$A$6:$A$55),"-")) -> - | T9: =IF(OR(I9="",Q9=""),"",IF(Q9<=I9-4,1,0)) | W9: =IF(OR($U9="",$V9="",$I9=""),"",IF(AND($U9<=$I9-4,$V9>=$F9),1,0)) | Y9: Amber Lines / Production per line = the order still has a balance but no capacity assigned, so it is not scheduled.
B10: M5 | C10: 3 | D10: 4301 | E10: 7243553175 | F10: 3693 | G10: 3693 | H10: =IF(OR(D10="",E10=""),"",IFERROR(F10-G10,"-")) -> 0 | I10: 46239 | J10: =IF(I10="","",IFERROR(WORKDAY.INTL(I10,-10,"0000001",Holidays!$A$6:$A$55),"-")) -> 46227 | M10: =IF(OR(D10="",E10="",F10="",K10="",L10=""),"",IFERROR(ROUNDUP(H10/(K10*L10),0),"-")) | N10: Close | O10: {=IF(OR($D10="",$E10=""),"",IF($N10<>"",$N10,IFERROR(WORKDAY.INTL(LOOKUP(2,1/(($D$2:D9=$D10)*ISNUMBER($P$2:P9)),$P$2:P9),1,"0000001",Holidays!$A$6:$A$55),"")))} -> Close | P10: =IF(OR(O10="",H10="",K10="",L10=""),"",IFERROR(WORKDAY.INTL(O10-1,MAX(1,ROUNDUP(H10/(K10*L10),0)),"0000001",Holidays!$A$6:$A$55),"-")) | Q10: =IF(P10="","",IFERROR(WORKDAY.INTL(P10,3,"0000001",Holidays!$A$6:$A$55),"-")) | R10: =IF(OR(J10="",P10=""),"",IFERROR(NETWORKDAYS.INTL(P10+1,J10,"0000001",Holidays!$A$6:$A$55),"-")) | S10: =IF(O10="","",IFERROR(WORKDAY.INTL(O10,-10,"0000001",Holidays!$A$6:$A$55),"-")) -> - | T10: =IF(OR(I10="",Q10=""),"",IF(Q10<=I10-4,1,0)) | W10: =IF(OR($U10="",$V10="",$I10=""),"",IF(AND($U10<=$I10-4,$V10>=$F10),1,0)) | Y10: Working days exclude Sundays and the dates listed on the Holidays sheet.
B11: M5 | C11: 4 | D11: 4301 | E11: 7906122198 | F11: 803 | G11: 586 | H11: =IF(OR(D11="",E11=""),"",IFERROR(F11-G11,"-")) -> 217 | I11: 46239 | J11: =IF(I11="","",IFERROR(WORKDAY.INTL(I11,-10,"0000001",Holidays!$A$6:$A$55),"-")) -> 46227 | M11: =IF(OR(D11="",E11="",F11="",K11="",L11=""),"",IFERROR(ROUNDUP(H11/(K11*L11),0),"-")) | N11: Close | O11: {=IF(OR($D11="",$E11=""),"",IF($N11<>"",$N11,IFERROR(WORKDAY.INTL(LOOKUP(2,1/(($D$2:D10=$D11)*ISNUMBER($P$2:P10)),$P$2:P10),1,"0000001",Holidays!$A$6:$A$55),"")))} -> Close | P11: =IF(OR(O11="",H11="",K11="",L11=""),"",IFERROR(WORKDAY.INTL(O11-1,MAX(1,ROUNDUP(H11/(K11*L11),0)),"0000001",Holidays!$A$6:$A$55),"-")) | Q11: =IF(P11="","",IFERROR(WORKDAY.INTL(P11,3,"0000001",Holidays!$A$6:$A$55),"-")) | R11: =IF(OR(J11="",P11=""),"",IFERROR(NETWORKDAYS.INTL(P11+1,J11,"0000001",Holidays!$A$6:$A$55),"-")) | S11: =IF(O11="","",IFERROR(WORKDAY.INTL(O11,-10,"0000001",Holidays!$A$6:$A$55),"-")) -> - | T11: =IF(OR(I11="",Q11=""),"",IF(Q11<=I11-4,1,0)) | W11: =IF(OR($U11="",$V11="",$I11=""),"",IF(AND($U11<=$I11-4,$V11>=$F11),1,0))
B12: M5 | C12: 5 | D12: 4301 | E12: 7972816177 | F12: 3374 | G12: 0 | H12: =IF(OR(D12="",E12=""),"",IFERROR(F12-G12,"-")) -> 3374 | I12: 46239 | J12: =IF(I12="","",IFERROR(WORKDAY.INTL(I12,-10,"0000001",Holidays!$A$6:$A$55),"-")) -> 46227 | K12: 1 | L12: 850 | M12: =IF(OR(D12="",E12="",F12="",K12="",L12=""),"",IFERROR(ROUNDUP(H12/(K12*L12),0),"-")) -> 4 | N12: 46247 | O12: {=IF(OR($D12="",$E12=""),"",IF($N12<>"",$N12,IFERROR(WORKDAY.INTL(LOOKUP(2,1/(($D$2:D11=$D12)*ISNUMBER($P$2:P11)),$P$2:P11),1,"0000001",Holidays!$A$6:$A$55),"")))} -> 46247 | P12: =IF(OR(O12="",H12="",K12="",L12=""),"",IFERROR(WORKDAY.INTL(O12-1,MAX(1,ROUNDUP(H12/(K12*L12),0)),"0000001",Holidays!$A$6:$A$55),"-")) -> 46252 | Q12: =IF(P12="","",IFERROR(WORKDAY.INTL(P12,3,"0000001",Holidays!$A$6:$A$55),"-")) -> 46255 | R12: =IF(OR(J12="",P12=""),"",IFERROR(NETWORKDAYS.INTL(P12+1,J12,"0000001",Holidays!$A$6:$A$55),"-")) -> -22 | S12: =IF(O12="","",IFERROR(WORKDAY.INTL(O12,-10,"0000001",Holidays!$A$6:$A$55),"-")) -> 46235 | T12: =IF(OR(I12="",Q12=""),"",IF(Q12<=I12-4,1,0)) -> 0 | W12: =IF(OR($U12="",$V12="",$I12=""),"",IF(AND($U12<=$I12-4,$V12>=$F12),1,0))
B13: M5 | C13: 6 | D13: 4301 | E13: 7529999468 | F13: 574 | G13: 0 | H13: =IF(OR(D13="",E13=""),"",IFERROR(F13-G13,"-")) -> 574 | I13: 46248 | J13: =IF(I13="","",IFERROR(WORKDAY.INTL(I13,-10,"0000001",Holidays!$A$6:$A$55),"-")) -> 46237 | K13: 1 | L13: 850 | M13: =IF(OR(D13="",E13="",F13="",K13="",L13=""),"",IFERROR(ROUNDUP(H13/(K13*L13),0),"-")) -> 1 | O13: {=IF(OR($D13="",$E13=""),"",IF($N13<>"",$N13,IFERROR(WORKDAY.INTL(LOOKUP(2,1/(($D$2:D12=$D13)*ISNUMBER($P$2:P12)),$P$2:P12),1,"0000001",Holidays!$A$6:$A$55),"")))} -> 46253 | P13: =IF(OR(O13="",H13="",K13="",L13=""),"",IFERROR(WORKDAY.INTL(O13-1,MAX(1,ROUNDUP(H13/(K13*L13),0)),"0000001",Holidays!$A$6:$A$55),"-")) -> 46253 | Q13: =IF(P13="","",IFERROR(WORKDAY.INTL(P13,3,"0000001",Holidays!$A$6:$A$55),"-")) -> 46256 | R13: =IF(OR(J13="",P13=""),"",IFERROR(NETWORKDAYS.INTL(P13+1,J13,"0000001",Holidays!$A$6:$A$55),"-")) -> -15 | S13: =IF(O13="","",IFERROR(WORKDAY.INTL(O13,-10,"0000001",Holidays!$A$6:$A$55),"-")) -> 46240 | T13: =IF(OR(I13="",Q13=""),"",IF(Q13<=I13-4,1,0)) -> 0 | W13: =IF(OR($U13="",$V13="",$I13=""),"",IF(AND($U13<=$I13-4,$V13>=$F13),1,0))
B14: M6 | C14: 7 | D14: 4301 | E14: 7532230827 | F14: 986 | G14: 0 | H14: =IF(OR(D14="",E14=""),"",IFERROR(F14-G14,"-")) -> 986 | I14: 46276 | J14: =IF(I14="","",IFERROR(WORKDAY.INTL(I14,-10,"0000001",Holidays!$A$6:$A$55),"-")) -> 46265 | K14: 1 | L14: 850 | M14: =IF(OR(D14="",E14="",F14="",K14="",L14=""),"",IFERROR(ROUNDUP(H14/(K14*L14),0),"-")) -> 2 | N14: 46266 | O14: {=IF(OR($D14="",$E14=""),"",IF($N14<>"",$N14,IFERROR(WORKDAY.INTL(LOOKUP(2,1/(($D$2:D13=$D14)*ISNUMBER($P$2:P13)),$P$2:P13),1,"0000001",Holidays!$A$6:$A$55),"")))} -> 46266 | P14: =IF(OR(O14="",H14="",K14="",L14=""),"",IFERROR(WORKDAY.INTL(O14-1,MAX(1,ROUNDUP(H14/(K14*L14),0)),"0000001",Holidays!$A$6:$A$55),"-")) -> 46267 | Q14: =IF(P14="","",IFERROR(WORKDAY.INTL(P14,3,"0000001",Holidays!$A$6:$A$55),"-")) -> 46270 | R14: =IF(OR(J14="",P14=""),"",IFERROR(NETWORKDAYS.INTL(P14+1,J14,"0000001",Holidays!$A$6:$A$55),"-")) -> -4 | S14: =IF(O14="","",IFERROR(WORKDAY.INTL(O14,-10,"0000001",Holidays!$A$6:$A$55),"-")) -> 46253 | T14: =IF(OR(I14="",Q14=""),"",IF(Q14<=I14-4,1,0)) -> 1 | W14: =IF(OR($U14="",$V14="",$I14=""),"",IF(AND($U14<=$I14-4,$V14>=$F14),1,0))
B15: M6 | C15: 8 | D15: 4301 | E15: 7114448904 | F15: 659 | G15: 659 | H15: =IF(OR(D15="",E15=""),"",IFERROR(F15-G15,"-")) -> 0 | I15: 46276 | J15: =IF(I15="","",IFERROR(WORKDAY.INTL(I15,-10,"0000001",Holidays!$A$6:$A$55),"-")) -> 46265 | K15: 1 | L15: 850 | M15: =IF(OR(D15="",E15="",F15="",K15="",L15=""),"",IFERROR(ROUNDUP(H15/(K15*L15),0),"-")) -> 0 | N15: 46265 | O15: {=IF(OR($D15="",$E15=""),"",IF($N15<>"",$N15,IFERROR(WORKDAY.INTL(LOOKUP(2,1/(($D$2:D14=$D15)*ISNUMBER($P$2:P14)),$P$2:P14),1,"0000001",Holidays!$A$6:$A$55),"")))} -> 46265 | P15: =IF(OR(O15="",H15="",K15="",L15=""),"",IFERROR(WORKDAY.INTL(O15-1,MAX(1,ROUNDUP(H15/(K15*L15),0)),"0000001",Holidays!$A$6:$A$55),"-")) -> 46265 | Q15: =IF(P15="","",IFERROR(WORKDAY.INTL(P15,3,"0000001",Holidays!$A$6:$A$55),"-")) -> 46268 | R15: =IF(OR(J15="",P15=""),"",IFERROR(NETWORKDAYS.INTL(P15+1,J15,"0000001",Holidays!$A$6:$A$55),"-")) -> -2 | S15: =IF(O15="","",IFERROR(WORKDAY.INTL(O15,-10,"0000001",Holidays!$A$6:$A$55),"-")) -> 46252 | T15: =IF(OR(I15="",Q15=""),"",IF(Q15<=I15-4,1,0)) -> 1 | W15: =IF(OR($U15="",$V15="",$I15=""),"",IF(AND($U15<=$I15-4,$V15>=$F15),1,0))
B16: M6 | C16: 9 | D16: 4301 | E16: 7373337622 | F16: 756 | G16: 0 | H16: =IF(OR(D16="",E16=""),"",IFERROR(F16-G16,"-")) -> 756 | I16: 46276 | J16: =IF(I16="","",IFERROR(WORKDAY.INTL(I16,-10,"0000001",Holidays!$A$6:$A$55),"-")) -> 46265 | K16: 1 | L16: 850 | M16: =IF(OR(D16="",E16="",F16="",K16="",L16=""),"",IFERROR(ROUNDUP(H16/(K16*L16),0),"-")) -> 1 | N16: 46263 | O16: {=IF(OR($D16="",$E16=""),"",IF($N16<>"",$N16,IFERROR(WORKDAY.INTL(LOOKUP(2,1/(($D$2:D15=$D16)*ISNUMBER($P$2:P15)),$P$2:P15),1,"0000001",Holidays!$A$6:$A$55),"")))} -> 46263 | P16: =IF(OR(O16="",H16="",K16="",L16=""),"",IFERROR(WORKDAY.INTL(O16-1,MAX(1,ROUNDUP(H16/(K16*L16),0)),"0000001",Holidays!$A$6:$A$55),"-")) -> 46263 | Q16: =IF(P16="","",IFERROR(WORKDAY.INTL(P16,3,"0000001",Holidays!$A$6:$A$55),"-")) -> 46267 | R16: =IF(OR(J16="",P16=""),"",IFERROR(NETWORKDAYS.INTL(P16+1,J16,"0000001",Holidays!$A$6:$A$55),"-")) -> 1 | S16: =IF(O16="","",IFERROR(WORKDAY.INTL(O16,-10,"0000001",Holidays!$A$6:$A$55),"-")) -> 46251 | T16: =IF(OR(I16="",Q16=""),"",IF(Q16<=I16-4,1,0)) -> 1 | W16: =IF(OR($U16="",$V16="",$I16=""),"",IF(AND($U16<=$I16-4,$V16>=$F16),1,0))
B17: M6 | C17: 10 | D17: 4301 | E17: 7665397029 | F17: 2924 | G17: 0 | H17: =IF(OR(D17="",E17=""),"",IFERROR(F17-G17,"-")) -> 2924 | I17: 46262 | J17: =IF(I17="","",IFERROR(WORKDAY.INTL(I17,-10,"0000001",Holidays!$A$6:$A$55),"-")) -> 46251 | K17: 1 | L17: 850 | M17: =IF(OR(D17="",E17="",F17="",K17="",L17=""),"",IFERROR(ROUNDUP(H17/(K17*L17),0),"-")) -> 4 | N17: 46267 | O17: {=IF(OR($D17="",$E17=""),"",IF($N17<>"",$N17,IFERROR(WORKDAY.INTL(LOOKUP(2,1/(($D$2:D16=$D17)*ISNUMBER($P$2:P16)),$P$2:P16),1,"0000001",Holidays!$A$6:$A$55),"")))} -> 46267 | P17: =IF(OR(O17="",H17="",K17="",L17=""),"",IFERROR(WORKDAY.INTL(O17-1,MAX(1,ROUNDUP(H17/(K17*L17),0)),"0000001",Holidays!$A$6:$A$55),"-")) -> 46270 | Q17: =IF(P17="","",IFERROR(WORKDAY.INTL(P17,3,"0000001",Holidays!$A$6:$A$55),"-")) -> 46274 | R17: =IF(OR(J17="",P17=""),"",IFERROR(NETWORKDAYS.INTL(P17+1,J17,"0000001",Holidays!$A$6:$A$55),"-")) -> -17 | S17: =IF(O17="","",IFERROR(WORKDAY.INTL(O17,-10,"0000001",Holidays!$A$6:$A$55),"-")) -> 46254 | T17: =IF(OR(I17="",Q17=""),"",IF(Q17<=I17-4,1,0)) -> 0 | W17: =IF(OR($U17="",$V17="",$I17=""),"",IF(AND($U17<=$I17-4,$V17>=$F17),1,0))
B18: M6 | C18: 11 | D18: 4301 | E18: 7916958755 | F18: 727 | G18: 489 | H18: =IF(OR(D18="",E18=""),"",IFERROR(F18-G18,"-")) -> 238 | I18: 46262 | J18: =IF(I18="","",IFERROR(WORKDAY.INTL(I18,-10,"0000001",Holidays!$A$6:$A$55),"-")) -> 46251 | K18: 1 | L18: 850 | M18: =IF(OR(D18="",E18="",F18="",K18="",L18=""),"",IFERROR(ROUNDUP(H18/(K18*L18),0),"-")) -> 1 | N18: 46270 | O18: {=IF(OR($D18="",$E18=""),"",IF($N18<>"",$N18,IFERROR(WORKDAY.INTL(LOOKUP(2,1/(($D$2:D17=$D18)*ISNUMBER($P$2:P17)),$P$2:P17),1,"0000001",Holidays!$A$6:$A$55),"")))} -> 46270 | P18: =IF(OR(O18="",H18="",K18="",L18=""),"",IFERROR(WORKDAY.INTL(O18-1,MAX(1,ROUNDUP(H18/(K18*L18),0)),"0000001",Holidays!$A$6:$A$55),"-")) -> 46270 | Q18: =IF(P18="","",IFERROR(WORKDAY.INTL(P18,3,"0000001",Holidays!$A$6:$A$55),"-")) -> 46274 | R18: =IF(OR(J18="",P18=""),"",IFERROR(NETWORKDAYS.INTL(P18+1,J18,"0000001",Holidays!$A$6:$A$55),"-")) -> -17 | S18: =IF(O18="","",IFERROR(WORKDAY.INTL(O18,-10,"0000001",Holidays!$A$6:$A$55),"-")) -> 46258 | T18: =IF(OR(I18="",Q18=""),"",IF(Q18<=I18-4,1,0)) -> 0 | W18: =IF(OR($U18="",$V18="",$I18=""),"",IF(AND($U18<=$I18-4,$V18>=$F18),1,0))
B19: M6 | C19: 12 | D19: 4301 | E19: 7207612821 | F19: 1071 | G19: 1071 | H19: =IF(OR(D19="",E19=""),"",IFERROR(F19-G19,"-")) -> 0 | I19: 46262 | J19: =IF(I19="","",IFERROR(WORKDAY.INTL(I19,-10,"0000001",Holidays!$A$6:$A$55),"-")) -> 46251 | K19: 1 | L19: 850 | M19: =IF(OR(D19="",E19="",F19="",K19="",L19=""),"",IFERROR(ROUNDUP(H19/(K19*L19),0),"-")) -> 0 | O19: {=IF(OR($D19="",$E19=""),"",IF($N19<>"",$N19,IFERROR(WORKDAY.INTL(LOOKUP(2,1/(($D$2:D18=$D19)*ISNUMBER($P$2:P18)),$P$2:P18),1,"0000001",Holidays!$A$6:$A$55),"")))} -> 46272 | P19: =IF(OR(O19="",H19="",K19="",L19=""),"",IFERROR(WORKDAY.INTL(O19-1,MAX(1,ROUNDUP(H19/(K19*L19),0)),"0000001",Holidays!$A$6:$A$55),"-")) -> 46272 | Q19: =IF(P19="","",IFERROR(WORKDAY.INTL(P19,3,"0000001",Holidays!$A$6:$A$55),"-")) -> 46275 | R19: =IF(OR(J19="",P19=""),"",IFERROR(NETWORKDAYS.INTL(P19+1,J19,"0000001",Holidays!$A$6:$A$55),"-")) -> -19 | S19: =IF(O19="","",IFERROR(WORKDAY.INTL(O19,-10,"0000001",Holidays!$A$6:$A$55),"-")) -> 46259 | T19: =IF(OR(I19="",Q19=""),"",IF(Q19<=I19-4,1,0)) -> 0 | W19: =IF(OR($U19="",$V19="",$I19=""),"",IF(AND($U19<=$I19-4,$V19>=$F19),1,0))
B20: M6 | C20: 13 | D20: 4301 | E20: 7883977575 | F20: 2520 | G20: 0 | H20: =IF(OR(D20="",E20=""),"",IFERROR(F20-G20,"-")) -> 2520 | I20: 46267 | J20: =IF(I20="","",IFERROR(WORKDAY.INTL(I20,-10,"0000001",Holidays!$A$6:$A$55),"-")) -> 46254 | K20: 1 | L20: 850 | M20: =IF(OR(D20="",E20="",F20="",K20="",L20=""),"",IFERROR(ROUNDUP(H20/(K20*L20),0),"-")) -> 3 | O20: {=IF(OR($D20="",$E20=""),"",IF($N20<>"",$N20,IFERROR(WORKDAY.INTL(LOOKUP(2,1/(($D$2:D19=$D20)*ISNUMBER($P$2:P19)),$P$2:P19),1,"0000001",Holidays!$A$6:$A$55),"")))} -> 46273 | P20: =IF(OR(O20="",H20="",K20="",L20=""),"",IFERROR(WORKDAY.INTL(O20-1,MAX(1,ROUNDUP(H20/(K20*L20),0)),"0000001",Holidays!$A$6:$A$55),"-")) -> 46275 | Q20: =IF(P20="","",IFERROR(WORKDAY.INTL(P20,3,"0000001",Holidays!$A$6:$A$55),"-")) -> 46279 | R20: =IF(OR(J20="",P20=""),"",IFERROR(NETWORKDAYS.INTL(P20+1,J20,"0000001",Holidays!$A$6:$A$55),"-")) -> -19 | S20: =IF(O20="","",IFERROR(WORKDAY.INTL(O20,-10,"0000001",Holidays!$A$6:$A$55),"-")) -> 46260 | T20: =IF(OR(I20="",Q20=""),"",IF(Q20<=I20-4,1,0)) -> 0 | W20: =IF(OR($U20="",$V20="",$I20=""),"",IF(AND($U20<=$I20-4,$V20>=$F20),1,0))
B21: M7 | C21: 14 | D21: 4301 | E21: 7902771789 | F21: 3804 | G21: 0 | H21: =IF(OR(D21="",E21=""),"",IFERROR(F21-G21,"-")) -> 3804 | I21: 46295 | J21: =IF(I21="","",IFERROR(WORKDAY.INTL(I21,-10,"0000001",Holidays!$A$6:$A$55),"-")) -> 46283 | K21: 1 | L21: 850 | M21: =IF(OR(D21="",E21="",F21="",K21="",L21=""),"",IFERROR(ROUNDUP(H21/(K21*L21),0),"-")) -> 5 | N21: 46277 | O21: {=IF(OR($D21="",$E21=""),"",IF($N21<>"",$N21,IFERROR(WORKDAY.INTL(LOOKUP(2,1/(($D$2:D20=$D21)*ISNUMBER($P$2:P20)),$P$2:P20),1,"0000001",Holidays!$A$6:$A$55),"")))} -> 46277 | P21: =IF(OR(O21="",H21="",K21="",L21=""),"",IFERROR(WORKDAY.INTL(O21-1,MAX(1,ROUNDUP(H21/(K21*L21),0)),"0000001",Holidays!$A$6:$A$55),"-")) -> 46282 | Q21: =IF(P21="","",IFERROR(WORKDAY.INTL(P21,3,"0000001",Holidays!$A$6:$A$55),"-")) -> 46286 | R21: =IF(OR(J21="",P21=""),"",IFERROR(NETWORKDAYS.INTL(P21+1,J21,"0000001",Holidays!$A$6:$A$55),"-")) -> 1 | S21: =IF(O21="","",IFERROR(WORKDAY.INTL(O21,-10,"0000001",Holidays!$A$6:$A$55),"-")) -> 46266 | T21: =IF(OR(I21="",Q21=""),"",IF(Q21<=I21-4,1,0)) -> 1 | W21: =IF(OR($U21="",$V21="",$I21=""),"",IF(AND($U21<=$I21-4,$V21>=$F21),1,0))
B22: M7 | C22: 15 | D22: 4301 | E22: 7861895544 | F22: 2495 | G22: 0 | H22: =IF(OR(D22="",E22=""),"",IFERROR(F22-G22,"-")) -> 2495 | I22: 46295 | J22: =IF(I22="","",IFERROR(WORKDAY.INTL(I22,-10,"0000001",Holidays!$A$6:$A$55),"-")) -> 46283 | K22: 1 | L22: 850 | M22: =IF(OR(D22="",E22="",F22="",K22="",L22=""),"",IFERROR(ROUNDUP(H22/(K22*L22),0),"-")) -> 3 | O22: {=IF(OR($D22="",$E22=""),"",IF($N22<>"",$N22,IFERROR(WORKDAY.INTL(LOOKUP(2,1/(($D$2:D21=$D22)*ISNUMBER($P$2:P21)),$P$2:P21),1,"0000001",Holidays!$A$6:$A$55),"")))} -> 46283 | P22: =IF(OR(O22="",H22="",K22="",L22=""),"",IFERROR(WORKDAY.INTL(O22-1,MAX(1,ROUNDUP(H22/(K22*L22),0)),"0000001",Holidays!$A$6:$A$55),"-")) -> 46286 | Q22: =IF(P22="","",IFERROR(WORKDAY.INTL(P22,3,"0000001",Holidays!$A$6:$A$55),"-")) -> 46289 | R22: =IF(OR(J22="",P22=""),"",IFERROR(NETWORKDAYS.INTL(P22+1,J22,"0000001",Holidays!$A$6:$A$55),"-")) -> -4 | S22: =IF(O22="","",IFERROR(WORKDAY.INTL(O22,-10,"0000001",Holidays!$A$6:$A$55),"-")) -> 46272 | T22: =IF(OR(I22="",Q22=""),"",IF(Q22<=I22-4,1,0)) -> 1 | W22: =IF(OR($U22="",$V22="",$I22=""),"",IF(AND($U22<=$I22-4,$V22>=$F22),1,0))
B23: M7 | C23: 16 | D23: 4301 | E23: 7589302773 | F23: 926 | G23: 0 | H23: =IF(OR(D23="",E23=""),"",IFERROR(F23-G23,"-")) -> 926 | I23: 46304 | J23: =IF(I23="","",IFERROR(WORKDAY.INTL(I23,-10,"0000001",Holidays!$A$6:$A$55),"-")) -> 46291 | K23: 1 | L23: 850 | M23: =IF(OR(D23="",E23="",F23="",K23="",L23=""),"",IFERROR(ROUNDUP(H23/(K23*L23),0),"-")) -> 2 | O23: {=IF(OR($D23="",$E23=""),"",IF($N23<>"",$N23,IFERROR(WORKDAY.INTL(LOOKUP(2,1/(($D$2:D22=$D23)*ISNUMBER($P$2:P22)),$P$2:P22),1,"0000001",Holidays!$A$6:$A$55),"")))} -> 46287 | P23: =IF(OR(O23="",H23="",K23="",L23=""),"",IFERROR(WORKDAY.INTL(O23-1,MAX(1,ROUNDUP(H23/(K23*L23),0)),"0000001",Holidays!$A$6:$A$55),"-")) -> 46288 | Q23: =IF(P23="","",IFERROR(WORKDAY.INTL(P23,3,"0000001",Holidays!$A$6:$A$55),"-")) -> 46291 | R23: =IF(OR(J23="",P23=""),"",IFERROR(NETWORKDAYS.INTL(P23+1,J23,"0000001",Holidays!$A$6:$A$55),"-")) -> 3 | S23: =IF(O23="","",IFERROR(WORKDAY.INTL(O23,-10,"0000001",Holidays!$A$6:$A$55),"-")) -> 46275 | T23: =IF(OR(I23="",Q23=""),"",IF(Q23<=I23-4,1,0)) -> 1 | W23: =IF(OR($U23="",$V23="",$I23=""),"",IF(AND($U23<=$I23-4,$V23>=$F23),1,0))
B24: M8 | C24: 17 | D24: 4301 | E24: 7435315852 | F24: 544 | G24: 0 | H24: =IF(OR(D24="",E24=""),"",IFERROR(F24-G24,"-")) -> 544 | I24: 46328 | J24: =IF(I24="","",IFERROR(WORKDAY.INTL(I24,-10,"0000001",Holidays!$A$6:$A$55),"-")) -> 46316 | K24: 1 | L24: 850 | M24: =IF(OR(D24="",E24="",F24="",K24="",L24=""),"",IFERROR(ROUNDUP(H24/(K24*L24),0),"-")) -> 1 | N24: 46288 | O24: {=IF(OR($D24="",$E24=""),"",IF($N24<>"",$N24,IFERROR(WORKDAY.INTL(LOOKUP(2,1/(($D$2:D23=$D24)*ISNUMBER($P$2:P23)),$P$2:P23),1,"0000001",Holidays!$A$6:$A$55),"")))} -> 46288 | P24: =IF(OR(O24="",H24="",K24="",L24=""),"",IFERROR(WORKDAY.INTL(O24-1,MAX(1,ROUNDUP(H24/(K24*L24),0)),"0000001",Holidays!$A$6:$A$55),"-")) -> 46288 | Q24: =IF(P24="","",IFERROR(WORKDAY.INTL(P24,3,"0000001",Holidays!$A$6:$A$55),"-")) -> 46291 | R24: =IF(OR(J24="",P24=""),"",IFERROR(NETWORKDAYS.INTL(P24+1,J24,"0000001",Holidays!$A$6:$A$55),"-")) -> 22 | S24: =IF(O24="","",IFERROR(WORKDAY.INTL(O24,-10,"0000001",Holidays!$A$6:$A$55),"-")) -> 46276 | T24: =IF(OR(I24="",Q24=""),"",IF(Q24<=I24-4,1,0)) -> 1 | W24: =IF(OR($U24="",$V24="",$I24=""),"",IF(AND($U24<=$I24-4,$V24>=$F24),1,0))
B25: M8 | C25: 18 | D25: 4301 | E25: 7879518413 | F25: 6668 | G25: 0 | H25: =IF(OR(D25="",E25=""),"",IFERROR(F25-G25,"-")) -> 6668 | I25: 46318 | J25: =IF(I25="","",IFERROR(WORKDAY.INTL(I25,-10,"0000001",Holidays!$A$6:$A$55),"-")) -> 46305 | K25: 1 | L25: 850 | M25: =IF(OR(D25="",E25="",F25="",K25="",L25=""),"",IFERROR(ROUNDUP(H25/(K25*L25),0),"-")) -> 8 | O25: {=IF(OR($D25="",$E25=""),"",IF($N25<>"",$N25,IFERROR(WORKDAY.INTL(LOOKUP(2,1/(($D$2:D24=$D25)*ISNUMBER($P$2:P24)),$P$2:P24),1,"0000001",Holidays!$A$6:$A$55),"")))} -> 46289 | P25: =IF(OR(O25="",H25="",K25="",L25=""),"",IFERROR(WORKDAY.INTL(O25-1,MAX(1,ROUNDUP(H25/(K25*L25),0)),"0000001",Holidays!$A$6:$A$55),"-")) -> 46298 | Q25: =IF(P25="","",IFERROR(WORKDAY.INTL(P25,3,"0000001",Holidays!$A$6:$A$55),"-")) -> 46302 | R25: =IF(OR(J25="",P25=""),"",IFERROR(NETWORKDAYS.INTL(P25+1,J25,"0000001",Holidays!$A$6:$A$55),"-")) -> 6 | S25: =IF(O25="","",IFERROR(WORKDAY.INTL(O25,-10,"0000001",Holidays!$A$6:$A$55),"-")) -> 46277 | T25: =IF(OR(I25="",Q25=""),"",IF(Q25<=I25-4,1,0)) -> 1 | W25: =IF(OR($U25="",$V25="",$I25=""),"",IF(AND($U25<=$I25-4,$V25>=$F25),1,0))
B26: M8 | C26: 19 | D26: 4301 | E26: 7352175804 | F26: 2231 | G26: 0 | H26: =IF(OR(D26="",E26=""),"",IFERROR(F26-G26,"-")) -> 2231 | I26: 46318 | J26: =IF(I26="","",IFERROR(WORKDAY.INTL(I26,-10,"0000001",Holidays!$A$6:$A$55),"-")) -> 46305 | K26: 1 | L26: 850 | M26: =IF(OR(D26="",E26="",F26="",K26="",L26=""),"",IFERROR(ROUNDUP(H26/(K26*L26),0),"-")) -> 3 | O26: {=IF(OR($D26="",$E26=""),"",IF($N26<>"",$N26,IFERROR(WORKDAY.INTL(LOOKUP(2,1/(($D$2:D25=$D26)*ISNUMBER($P$2:P25)),$P$2:P25),1,"0000001",Holidays!$A$6:$A$55),"")))} -> 46300 | P26: =IF(OR(O26="",H26="",K26="",L26=""),"",IFERROR(WORKDAY.INTL(O26-1,MAX(1,ROUNDUP(H26/(K26*L26),0)),"0000001",Holidays!$A$6:$A$55),"-")) -> 46302 | Q26: =IF(P26="","",IFERROR(WORKDAY.INTL(P26,3,"0000001",Holidays!$A$6:$A$55),"-")) -> 46305 | R26: =IF(OR(J26="",P26=""),"",IFERROR(NETWORKDAYS.INTL(P26+1,J26,"0000001",Holidays!$A$6:$A$55),"-")) -> 3 | S26: =IF(O26="","",IFERROR(WORKDAY.INTL(O26,-10,"0000001",Holidays!$A$6:$A$55),"-")) -> 46287 | T26: =IF(OR(I26="",Q26=""),"",IF(Q26<=I26-4,1,0)) -> 1 | W26: =IF(OR($U26="",$V26="",$I26=""),"",IF(AND($U26<=$I26-4,$V26>=$F26),1,0))
B27: M8 | C27: 20 | D27: 4301 | E27: 7345360217 | F27: 2796 | G27: 0 | H27: =IF(OR(D27="",E27=""),"",IFERROR(F27-G27,"-")) -> 2796 | I27: 46318 | J27: =IF(I27="","",IFERROR(WORKDAY.INTL(I27,-10,"0000001",Holidays!$A$6:$A$55),"-")) -> 46305 | K27: 1 | L27: 850 | M27: =IF(OR(D27="",E27="",F27="",K27="",L27=""),"",IFERROR(ROUNDUP(H27/(K27*L27),0),"-")) -> 4 | O27: {=IF(OR($D27="",$E27=""),"",IF($N27<>"",$N27,IFERROR(WORKDAY.INTL(LOOKUP(2,1/(($D$2:D26=$D27)*ISNUMBER($P$2:P26)),$P$2:P26),1,"0000001",Holidays!$A$6:$A$55),"")))} -> 46303 | P27: =IF(OR(O27="",H27="",K27="",L27=""),"",IFERROR(WORKDAY.INTL(O27-1,MAX(1,ROUNDUP(H27/(K27*L27),0)),"0000001",Holidays!$A$6:$A$55),"-")) -> 46307 | Q27: =IF(P27="","",IFERROR(WORKDAY.INTL(P27,3,"0000001",Holidays!$A$6:$A$55),"-")) -> 46310 | R27: =IF(OR(J27="",P27=""),"",IFERROR(NETWORKDAYS.INTL(P27+1,J27,"0000001",Holidays!$A$6:$A$55),"-")) -> -3 | S27: =IF(O27="","",IFERROR(WORKDAY.INTL(O27,-10,"0000001",Holidays!$A$6:$A$55),"-")) -> 46290 | T27: =IF(OR(I27="",Q27=""),"",IF(Q27<=I27-4,1,0)) -> 1 | W27: =IF(OR($U27="",$V27="",$I27=""),"",IF(AND($U27<=$I27-4,$V27>=$F27),1,0))
B28: M9 | C28: 21 | D28: 4301 | E28: 7170179588 | F28: 3145 | G28: 0 | H28: =IF(OR(D28="",E28=""),"",IFERROR(F28-G28,"-")) -> 3145 | I28: 46348 | J28: =IF(I28="","",IFERROR(WORKDAY.INTL(I28,-10,"0000001",Holidays!$A$6:$A$55),"-")) -> 46336 | K28: 1 | L28: 850 | M28: =IF(OR(D28="",E28="",F28="",K28="",L28=""),"",IFERROR(ROUNDUP(H28/(K28*L28),0),"-")) -> 4 | N28: 46307 | O28: {=IF(OR($D28="",$E28=""),"",IF($N28<>"",$N28,IFERROR(WORKDAY.INTL(LOOKUP(2,1/(($D$2:D27=$D28)*ISNUMBER($P$2:P27)),$P$2:P27),1,"0000001",Holidays!$A$6:$A$55),"")))} -> 46307 | P28: =IF(OR(O28="",H28="",K28="",L28=""),"",IFERROR(WORKDAY.INTL(O28-1,MAX(1,ROUNDUP(H28/(K28*L28),0)),"0000001",Holidays!$A$6:$A$55),"-")) -> 46310 | Q28: =IF(P28="","",IFERROR(WORKDAY.INTL(P28,3,"0000001",Holidays!$A$6:$A$55),"-")) -> 46314 | R28: =IF(OR(J28="",P28=""),"",IFERROR(NETWORKDAYS.INTL(P28+1,J28,"0000001",Holidays!$A$6:$A$55),"-")) -> 20 | S28: =IF(O28="","",IFERROR(WORKDAY.INTL(O28,-10,"0000001",Holidays!$A$6:$A$55),"-")) -> 46294 | T28: =IF(OR(I28="",Q28=""),"",IF(Q28<=I28-4,1,0)) -> 1 | W28: =IF(OR($U28="",$V28="",$I28=""),"",IF(AND($U28<=$I28-4,$V28>=$F28),1,0))
B29: M9 | C29: 22 | D29: 4301 | E29: 7881088803 | F29: 1708 | G29: 0 | H29: =IF(OR(D29="",E29=""),"",IFERROR(F29-G29,"-")) -> 1708 | I29: 46356 | J29: =IF(I29="","",IFERROR(WORKDAY.INTL(I29,-10,"0000001",Holidays!$A$6:$A$55),"-")) -> 46344 | K29: 1 | L29: 850 | M29: =IF(OR(D29="",E29="",F29="",K29="",L29=""),"",IFERROR(ROUNDUP(H29/(K29*L29),0),"-")) -> 3 | O29: {=IF(OR($D29="",$E29=""),"",IF($N29<>"",$N29,IFERROR(WORKDAY.INTL(LOOKUP(2,1/(($D$2:D28=$D29)*ISNUMBER($P$2:P28)),$P$2:P28),1,"0000001",Holidays!$A$6:$A$55),"")))} -> 46311 | P29: =IF(OR(O29="",H29="",K29="",L29=""),"",IFERROR(WORKDAY.INTL(O29-1,MAX(1,ROUNDUP(H29/(K29*L29),0)),"0000001",Holidays!$A$6:$A$55),"-")) -> 46314 | Q29: =IF(P29="","",IFERROR(WORKDAY.INTL(P29,3,"0000001",Holidays!$A$6:$A$55),"-")) -> 46318 | R29: =IF(OR(J29="",P29=""),"",IFERROR(NETWORKDAYS.INTL(P29+1,J29,"0000001",Holidays!$A$6:$A$55),"-")) -> 23 | S29: =IF(O29="","",IFERROR(WORKDAY.INTL(O29,-10,"0000001",Holidays!$A$6:$A$55),"-")) -> 46300 | T29: =IF(OR(I29="",Q29=""),"",IF(Q29<=I29-4,1,0)) -> 1 | W29: =IF(OR($U29="",$V29="",$I29=""),"",IF(AND($U29<=$I29-4,$V29>=$F29),1,0))
B30: M5 | C30: 1 | D30: 6820 | E30: 7232615519 | F30: 64328 | G30: 64328 | H30: =IF(OR(D30="",E30=""),"",IFERROR(F30-G30,"-")) -> 0 | I30: 46241 | J30: =IF(I30="","",IFERROR(WORKDAY.INTL(I30,-10,"0000001",Holidays!$A$6:$A$55),"-")) -> 46230 | M30: =IF(OR(D30="",E30="",F30="",K30="",L30=""),"",IFERROR(ROUNDUP(H30/(K30*L30),0),"-")) | N30: Close | O30: {=IF(OR($D30="",$E30=""),"",IF($N30<>"",$N30,IFERROR(WORKDAY.INTL(LOOKUP(2,1/(($D$2:D29=$D30)*ISNUMBER($P$2:P29)),$P$2:P29),1,"0000001",Holidays!$A$6:$A$55),"")))} -> Close | P30: =IF(OR(O30="",H30="",K30="",L30=""),"",IFERROR(WORKDAY.INTL(O30-1,MAX(1,ROUNDUP(H30/(K30*L30),0)),"0000001",Holidays!$A$6:$A$55),"-")) | Q30: =IF(P30="","",IFERROR(WORKDAY.INTL(P30,3,"0000001",Holidays!$A$6:$A$55),"-")) | R30: =IF(OR(J30="",P30=""),"",IFERROR(NETWORKDAYS.INTL(P30+1,J30,"0000001",Holidays!$A$6:$A$55),"-")) | S30: =IF(O30="","",IFERROR(WORKDAY.INTL(O30,-10,"0000001",Holidays!$A$6:$A$55),"-")) -> - | T30: =IF(OR(I30="",Q30=""),"",IF(Q30<=I30-4,1,0)) | W30: =IF(OR($U30="",$V30="",$I30=""),"",IF(AND($U30<=$I30-4,$V30>=$F30),1,0))
B31: M5 | C31: 2 | D31: 6820 | E31: 7121610466 | F31: 63716 | G31: 63716 | H31: =IF(OR(D31="",E31=""),"",IFERROR(F31-G31,"-")) -> 0 | I31: 46241 | J31: =IF(I31="","",IFERROR(WORKDAY.INTL(I31,-10,"0000001",Holidays!$A$6:$A$55),"-")) -> 46230 | M31: =IF(OR(D31="",E31="",F31="",K31="",L31=""),"",IFERROR(ROUNDUP(H31/(K31*L31),0),"-")) | N31: Close | O31: {=IF(OR($D31="",$E31=""),"",IF($N31<>"",$N31,IFERROR(WORKDAY.INTL(LOOKUP(2,1/(($D$2:D30=$D31)*ISNUMBER($P$2:P30)),$P$2:P30),1,"0000001",Holidays!$A$6:$A$55),"")))} -> Close | P31: =IF(OR(O31="",H31="",K31="",L31=""),"",IFERROR(WORKDAY.INTL(O31-1,MAX(1,ROUNDUP(H31/(K31*L31),0)),"0000001",Holidays!$A$6:$A$55),"-")) | Q31: =IF(P31="","",IFERROR(WORKDAY.INTL(P31,3,"0000001",Holidays!$A$6:$A$55),"-")) | R31: =IF(OR(J31="",P31=""),"",IFERROR(NETWORKDAYS.INTL(P31+1,J31,"0000001",Holidays!$A$6:$A$55),"-")) | S31: =IF(O31="","",IFERROR(WORKDAY.INTL(O31,-10,"0000001",Holidays!$A$6:$A$55),"-")) -> - | T31: =IF(OR(I31="",Q31=""),"",IF(Q31<=I31-4,1,0)) | W31: =IF(OR($U31="",$V31="",$I31=""),"",IF(AND($U31<=$I31-4,$V31>=$F31),1,0))
B32: M6 | C32: 3 | D32: 6820 | E32: 7161255896 | F32: 51544 | G32: 51544 | H32: =IF(OR(D32="",E32=""),"",IFERROR(F32-G32,"-")) -> 0 | I32: 46268 | J32: =IF(I32="","",IFERROR(WORKDAY.INTL(I32,-10,"0000001",Holidays!$A$6:$A$55),"-")) -> 46255 | M32: =IF(OR(D32="",E32="",F32="",K32="",L32=""),"",IFERROR(ROUNDUP(H32/(K32*L32),0),"-")) | N32: Close | O32: {=IF(OR($D32="",$E32=""),"",IF($N32<>"",$N32,IFERROR(WORKDAY.INTL(LOOKUP(2,1/(($D$2:D31=$D32)*ISNUMBER($P$2:P31)),$P$2:P31),1,"0000001",Holidays!$A$6:$A$55),"")))} -> Close | P32: =IF(OR(O32="",H32="",K32="",L32=""),"",IFERROR(WORKDAY.INTL(O32-1,MAX(1,ROUNDUP(H32/(K32*L32),0)),"0000001",Holidays!$A$6:$A$55),"-")) | Q32: =IF(P32="","",IFERROR(WORKDAY.INTL(P32,3,"0000001",Holidays!$A$6:$A$55),"-")) | R32: =IF(OR(J32="",P32=""),"",IFERROR(NETWORKDAYS.INTL(P32+1,J32,"0000001",Holidays!$A$6:$A$55),"-")) | S32: =IF(O32="","",IFERROR(WORKDAY.INTL(O32,-10,"0000001",Holidays!$A$6:$A$55),"-")) -> - | T32: =IF(OR(I32="",Q32=""),"",IF(Q32<=I32-4,1,0)) | W32: =IF(OR($U32="",$V32="",$I32=""),"",IF(AND($U32<=$I32-4,$V32>=$F32),1,0))
B33: M6 | C33: 4 | D33: 6820 | E33: 7330599164 | F33: 51136 | G33: 51136 | H33: =IF(OR(D33="",E33=""),"",IFERROR(F33-G33,"-")) -> 0 | I33: 46268 | J33: =IF(I33="","",IFERROR(WORKDAY.INTL(I33,-10,"0000001",Holidays!$A$6:$A$55),"-")) -> 46255 | M33: =IF(OR(D33="",E33="",F33="",K33="",L33=""),"",IFERROR(ROUNDUP(H33/(K33*L33),0),"-")) | N33: Close | O33: {=IF(OR($D33="",$E33=""),"",IF($N33<>"",$N33,IFERROR(WORKDAY.INTL(LOOKUP(2,1/(($D$2:D32=$D33)*ISNUMBER($P$2:P32)),$P$2:P32),1,"0000001",Holidays!$A$6:$A$55),"")))} -> Close | P33: =IF(OR(O33="",H33="",K33="",L33=""),"",IFERROR(WORKDAY.INTL(O33-1,MAX(1,ROUNDUP(H33/(K33*L33),0)),"0000001",Holidays!$A$6:$A$55),"-")) | Q33: =IF(P33="","",IFERROR(WORKDAY.INTL(P33,3,"0000001",Holidays!$A$6:$A$55),"-")) | R33: =IF(OR(J33="",P33=""),"",IFERROR(NETWORKDAYS.INTL(P33+1,J33,"0000001",Holidays!$A$6:$A$55),"-")) | S33: =IF(O33="","",IFERROR(WORKDAY.INTL(O33,-10,"0000001",Holidays!$A$6:$A$55),"-")) -> - | T33: =IF(OR(I33="",Q33=""),"",IF(Q33<=I33-4,1,0)) | W33: =IF(OR($U33="",$V33="",$I33=""),"",IF(AND($U33<=$I33-4,$V33>=$F33),1,0))
B34: M7 | C34: 5 | D34: 6820 | E34: 7447514654 | F34: 59330 | G34: 44573 | H34: =IF(OR(D34="",E34=""),"",IFERROR(F34-G34,"-")) -> 14757 | I34: 46302 | J34: =IF(I34="","",IFERROR(WORKDAY.INTL(I34,-10,"0000001",Holidays!$A$6:$A$55),"-")) -> 46289 | K34: 1 | L34: 4250 | M34: =IF(OR(D34="",E34="",F34="",K34="",L34=""),"",IFERROR(ROUNDUP(H34/(K34*L34),0),"-")) -> 4 | N34: 46247 | O34: {=IF(OR($D34="",$E34=""),"",IF($N34<>"",$N34,IFERROR(WORKDAY.INTL(LOOKUP(2,1/(($D$2:D33=$D34)*ISNUMBER($P$2:P33)),$P$2:P33),1,"0000001",Holidays!$A$6:$A$55),"")))} -> 46247 | P34: =IF(OR(O34="",H34="",K34="",L34=""),"",IFERROR(WORKDAY.INTL(O34-1,MAX(1,ROUNDUP(H34/(K34*L34),0)),"0000001",Holidays!$A$6:$A$55),"-")) -> 46252 | Q34: =IF(P34="","",IFERROR(WORKDAY.INTL(P34,3,"0000001",Holidays!$A$6:$A$55),"-")) -> 46255 | R34: =IF(OR(J34="",P34=""),"",IFERROR(NETWORKDAYS.INTL(P34+1,J34,"0000001",Holidays!$A$6:$A$55),"-")) -> 31 | S34: =IF(O34="","",IFERROR(WORKDAY.INTL(O34,-10,"0000001",Holidays!$A$6:$A$55),"-")) -> 46235 | T34: =IF(OR(I34="",Q34=""),"",IF(Q34<=I34-4,1,0)) -> 1 | W34: =IF(OR($U34="",$V34="",$I34=""),"",IF(AND($U34<=$I34-4,$V34>=$F34),1,0))
B35: M7 | C35: 6 | D35: 6820 | E35: 7170997977 | F35: 41922 | G35: 0 | H35: =IF(OR(D35="",E35=""),"",IFERROR(F35-G35,"-")) -> 41922 | I35: 46302 | J35: =IF(I35="","",IFERROR(WORKDAY.INTL(I35,-10,"0000001",Holidays!$A$6:$A$55),"-")) -> 46289 | K35: 1 | L35: 4250 | M35: =IF(OR(D35="",E35="",F35="",K35="",L35=""),"",IFERROR(ROUNDUP(H35/(K35*L35),0),"-")) -> 10 | N35: 46260 | O35: {=IF(OR($D35="",$E35=""),"",IF($N35<>"",$N35,IFERROR(WORKDAY.INTL(LOOKUP(2,1/(($D$2:D34=$D35)*ISNUMBER($P$2:P34)),$P$2:P34),1,"0000001",Holidays!$A$6:$A$55),"")))} -> 46260 | P35: =IF(OR(O35="",H35="",K35="",L35=""),"",IFERROR(WORKDAY.INTL(O35-1,MAX(1,ROUNDUP(H35/(K35*L35),0)),"0000001",Holidays!$A$6:$A$55),"-")) -> 46272 | Q35: =IF(P35="","",IFERROR(WORKDAY.INTL(P35,3,"0000001",Holidays!$A$6:$A$55),"-")) -> 46275 | R35: =IF(OR(J35="",P35=""),"",IFERROR(NETWORKDAYS.INTL(P35+1,J35,"0000001",Holidays!$A$6:$A$55),"-")) -> 15 | S35: =IF(O35="","",IFERROR(WORKDAY.INTL(O35,-10,"0000001",Holidays!$A$6:$A$55),"-")) -> 46247 | T35: =IF(OR(I35="",Q35=""),"",IF(Q35<=I35-4,1,0)) -> 1 | W35: =IF(OR($U35="",$V35="",$I35=""),"",IF(AND($U35<=$I35-4,$V35>=$F35),1,0))
B36: M5 | C36: 1 | D36: RS26 | E36: 7627387866 | F36: 18062 | G36: 18062 | H36: =IF(OR(D36="",E36=""),"",IFERROR(F36-G36,"-")) -> 0 | I36: 46247 | J36: =IF(I36="","",IFERROR(WORKDAY.INTL(I36,-10,"0000001",Holidays!$A$6:$A$55),"-")) -> 46235 | M36: =IF(OR(D36="",E36="",F36="",K36="",L36=""),"",IFERROR(ROUNDUP(H36/(K36*L36),0),"-")) | N36: Close | O36: {=IF(OR($D36="",$E36=""),"",IF($N36<>"",$N36,IFERROR(WORKDAY.INTL(LOOKUP(2,1/(($D$2:D35=$D36)*ISNUMBER($P$2:P35)),$P$2:P35),1,"0000001",Holidays!$A$6:$A$55),"")))} -> Close | P36: =IF(OR(O36="",H36="",K36="",L36=""),"",IFERROR(WORKDAY.INTL(O36-1,MAX(1,ROUNDUP(H36/(K36*L36),0)),"0000001",Holidays!$A$6:$A$55),"-")) | Q36: =IF(P36="","",IFERROR(WORKDAY.INTL(P36,3,"0000001",Holidays!$A$6:$A$55),"-")) | R36: =IF(OR(J36="",P36=""),"",IFERROR(NETWORKDAYS.INTL(P36+1,J36,"0000001",Holidays!$A$6:$A$55),"-")) | S36: =IF(O36="","",IFERROR(WORKDAY.INTL(O36,-10,"0000001",Holidays!$A$6:$A$55),"-")) -> - | T36: =IF(OR(I36="",Q36=""),"",IF(Q36<=I36-4,1,0)) | W36: =IF(OR($U36="",$V36="",$I36=""),"",IF(AND($U36<=$I36-4,$V36>=$F36),1,0))
B37: M5 | C37: 2 | D37: RS26 | E37: 7644351419 | F37: 5453 | G37: 5453 | H37: =IF(OR(D37="",E37=""),"",IFERROR(F37-G37,"-")) -> 0 | I37: 46247 | J37: =IF(I37="","",IFERROR(WORKDAY.INTL(I37,-10,"0000001",Holidays!$A$6:$A$55),"-")) -> 46235 | M37: =IF(OR(D37="",E37="",F37="",K37="",L37=""),"",IFERROR(ROUNDUP(H37/(K37*L37),0),"-")) | N37: Close | O37: {=IF(OR($D37="",$E37=""),"",IF($N37<>"",$N37,IFERROR(WORKDAY.INTL(LOOKUP(2,1/(($D$2:D36=$D37)*ISNUMBER($P$2:P36)),$P$2:P36),1,"0000001",Holidays!$A$6:$A$55),"")))} -> Close | P37: =IF(OR(O37="",H37="",K37="",L37=""),"",IFERROR(WORKDAY.INTL(O37-1,MAX(1,ROUNDUP(H37/(K37*L37),0)),"0000001",Holidays!$A$6:$A$55),"-")) | Q37: =IF(P37="","",IFERROR(WORKDAY.INTL(P37,3,"0000001",Holidays!$A$6:$A$55),"-")) | R37: =IF(OR(J37="",P37=""),"",IFERROR(NETWORKDAYS.INTL(P37+1,J37,"0000001",Holidays!$A$6:$A$55),"-")) | S37: =IF(O37="","",IFERROR(WORKDAY.INTL(O37,-10,"0000001",Holidays!$A$6:$A$55),"-")) -> - | T37: =IF(OR(I37="",Q37=""),"",IF(Q37<=I37-4,1,0)) | W37: =IF(OR($U37="",$V37="",$I37=""),"",IF(AND($U37<=$I37-4,$V37>=$F37),1,0))
B38: M5 | C38: 3 | D38: RS26 | E38: 7143748653 | F38: 5958 | G38: 5958 | H38: =IF(OR(D38="",E38=""),"",IFERROR(F38-G38,"-")) -> 0 | I38: 46247 | J38: =IF(I38="","",IFERROR(WORKDAY.INTL(I38,-10,"0000001",Holidays!$A$6:$A$55),"-")) -> 46235 | M38: =IF(OR(D38="",E38="",F38="",K38="",L38=""),"",IFERROR(ROUNDUP(H38/(K38*L38),0),"-")) | N38: Close | O38: {=IF(OR($D38="",$E38=""),"",IF($N38<>"",$N38,IFERROR(WORKDAY.INTL(LOOKUP(2,1/(($D$2:D37=$D38)*ISNUMBER($P$2:P37)),$P$2:P37),1,"0000001",Holidays!$A$6:$A$55),"")))} -> Close | P38: =IF(OR(O38="",H38="",K38="",L38=""),"",IFERROR(WORKDAY.INTL(O38-1,MAX(1,ROUNDUP(H38/(K38*L38),0)),"0000001",Holidays!$A$6:$A$55),"-")) | Q38: =IF(P38="","",IFERROR(WORKDAY.INTL(P38,3,"0000001",Holidays!$A$6:$A$55),"-")) | R38: =IF(OR(J38="",P38=""),"",IFERROR(NETWORKDAYS.INTL(P38+1,J38,"0000001",Holidays!$A$6:$A$55),"-")) | S38: =IF(O38="","",IFERROR(WORKDAY.INTL(O38,-10,"0000001",Holidays!$A$6:$A$55),"-")) -> - | T38: =IF(OR(I38="",Q38=""),"",IF(Q38<=I38-4,1,0)) | W38: =IF(OR($U38="",$V38="",$I38=""),"",IF(AND($U38<=$I38-4,$V38>=$F38),1,0))
B39: M5 | C39: 4 | D39: RS26 | E39: 7704849162 | F39: 5504 | G39: 5504 | H39: =IF(OR(D39="",E39=""),"",IFERROR(F39-G39,"-")) -> 0 | I39: 46247 | J39: =IF(I39="","",IFERROR(WORKDAY.INTL(I39,-10,"0000001",Holidays!$A$6:$A$55),"-")) -> 46235 | M39: =IF(OR(D39="",E39="",F39="",K39="",L39=""),"",IFERROR(ROUNDUP(H39/(K39*L39),0),"-")) | N39: Close | O39: {=IF(OR($D39="",$E39=""),"",IF($N39<>"",$N39,IFERROR(WORKDAY.INTL(LOOKUP(2,1/(($D$2:D38=$D39)*ISNUMBER($P$2:P38)),$P$2:P38),1,"0000001",Holidays!$A$6:$A$55),"")))} -> Close | P39: =IF(OR(O39="",H39="",K39="",L39=""),"",IFERROR(WORKDAY.INTL(O39-1,MAX(1,ROUNDUP(H39/(K39*L39),0)),"0000001",Holidays!$A$6:$A$55),"-")) | Q39: =IF(P39="","",IFERROR(WORKDAY.INTL(P39,3,"0000001",Holidays!$A$6:$A$55),"-")) | R39: =IF(OR(J39="",P39=""),"",IFERROR(NETWORKDAYS.INTL(P39+1,J39,"0000001",Holidays!$A$6:$A$55),"-")) | S39: =IF(O39="","",IFERROR(WORKDAY.INTL(O39,-10,"0000001",Holidays!$A$6:$A$55),"-")) -> - | T39: =IF(OR(I39="",Q39=""),"",IF(Q39<=I39-4,1,0)) | W39: =IF(OR($U39="",$V39="",$I39=""),"",IF(AND($U39<=$I39-4,$V39>=$F39),1,0))
B40: M5 | C40: 5 | D40: RS26 | E40: 7493971231 | F40: 9524 | G40: 9524 | H40: =IF(OR(D40="",E40=""),"",IFERROR(F40-G40,"-")) -> 0 | I40: 46251 | J40: =IF(I40="","",IFERROR(WORKDAY.INTL(I40,-10,"0000001",Holidays!$A$6:$A$55),"-")) -> 46238 | M40: =IF(OR(D40="",E40="",F40="",K40="",L40=""),"",IFERROR(ROUNDUP(H40/(K40*L40),0),"-")) | N40: Close | O40: {=IF(OR($D40="",$E40=""),"",IF($N40<>"",$N40,IFERROR(WORKDAY.INTL(LOOKUP(2,1/(($D$2:D39=$D40)*ISNUMBER($P$2:P39)),$P$2:P39),1,"0000001",Holidays!$A$6:$A$55),"")))} -> Close | P40: =IF(OR(O40="",H40="",K40="",L40=""),"",IFERROR(WORKDAY.INTL(O40-1,MAX(1,ROUNDUP(H40/(K40*L40),0)),"0000001",Holidays!$A$6:$A$55),"-")) | Q40: =IF(P40="","",IFERROR(WORKDAY.INTL(P40,3,"0000001",Holidays!$A$6:$A$55),"-")) | R40: =IF(OR(J40="",P40=""),"",IFERROR(NETWORKDAYS.INTL(P40+1,J40,"0000001",Holidays!$A$6:$A$55),"-")) | S40: =IF(O40="","",IFERROR(WORKDAY.INTL(O40,-10,"0000001",Holidays!$A$6:$A$55),"-")) -> - | T40: =IF(OR(I40="",Q40=""),"",IF(Q40<=I40-4,1,0)) | W40: =IF(OR($U40="",$V40="",$I40=""),"",IF(AND($U40<=$I40-4,$V40>=$F40),1,0))
...

Sheet Holidays
A1: HOLIDAYS & WORKING CALENDAR
A2: Calendar Year | B2: 2026 | E2: Legend | F2: Working | G2: Sunday | H2: Holiday
A3: Edit the yellow cells only: set the year in B2 and list holiday dates (and names) in A6:B55. Sundays are excluded automatically.
A4: Holiday Register | E4: Annual Working Calendar
A5: Holiday Date | B5: Holiday Name | C5: Notes | E5: Date | F5: Month | G5: Week | H5: Day | I5: Status | J5: Counted?
A6: 46048 | E6: =DATE($B$2,1,1) -> 46023 | F6: =IF(E6="","",TEXT(E6,"mmm")) -> Jan | G6: =IF(E6="","",WEEKNUM(E6,2)) -> 1 | H6: =IF(E6="","",TEXT(E6,"ddd")) -> Thu | I6: =IF(E6="","",IF(COUNTIF($A$6:$A$55,E6)>0,"Holiday",IF(WEEKDAY(E6,2)=7,"Sunday","Working"))) -> Working | J6: =IF(E6="","",IF(OR(WEEKDAY(E6,2)=7,COUNTIF($A$6:$A$55,E6)>0),"No","Yes")) -> Yes
A7: 46249 | E7: =IF(E6="","",IF(E6<DATE($B$2+1,1,1)-1,E6+1,"")) -> 46024 | F7: =IF(E7="","",TEXT(E7,"mmm")) -> Jan | G7: =IF(E7="","",WEEKNUM(E7,2)) -> 1 | H7: =IF(E7="","",TEXT(E7,"ddd")) -> Fri | I7: =IF(E7="","",IF(COUNTIF($A$6:$A$55,E7)>0,"Holiday",IF(WEEKDAY(E7,2)=7,"Sunday","Working"))) -> Working | J7: =IF(E7="","",IF(OR(WEEKDAY(E7,2)=7,COUNTIF($A$6:$A$55,E7)>0),"No","Yes")) -> Yes
A8: 46262 | E8: =IF(E7="","",IF(E7<DATE($B$2+1,1,1)-1,E7+1,"")) -> 46025 | F8: =IF(E8="","",TEXT(E8,"mmm")) -> Jan | G8: =IF(E8="","",WEEKNUM(E8,2)) -> 1 | H8: =IF(E8="","",TEXT(E8,"ddd")) -> Sat | I8: =IF(E8="","",IF(COUNTIF($A$6:$A$55,E8)>0,"Holiday",IF(WEEKDAY(E8,2)=7,"Sunday","Working"))) -> Working | J8: =IF(E8="","",IF(OR(WEEKDAY(E8,2)=7,COUNTIF($A$6:$A$55,E8)>0),"No","Yes")) -> Yes
A9: 46297 | E9: =IF(E8="","",IF(E8<DATE($B$2+1,1,1)-1,E8+1,"")) -> 46026 | F9: =IF(E9="","",TEXT(E9,"mmm")) -> Jan | G9: =IF(E9="","",WEEKNUM(E9,2)) -> 1 | H9: =IF(E9="","",TEXT(E9,"ddd")) -> Sun | I9: =IF(E9="","",IF(COUNTIF($A$6:$A$55,E9)>0,"Holiday",IF(WEEKDAY(E9,2)=7,"Sunday","Working"))) -> Sunday | J9: =IF(E9="","",IF(OR(WEEKDAY(E9,2)=7,COUNTIF($A$6:$A$55,E9)>0),"No","Yes")) -> No
A10: 46315 | E10: =IF(E9="","",IF(E9<DATE($B$2+1,1,1)-1,E9+1,"")) -> 46027 | F10: =IF(E10="","",TEXT(E10,"mmm")) -> Jan | G10: =IF(E10="","",WEEKNUM(E10,2)) -> 2 | H10: =IF(E10="","",TEXT(E10,"ddd")) -> Mon | I10: =IF(E10="","",IF(COUNTIF($A$6:$A$55,E10)>0,"Holiday",IF(WEEKDAY(E10,2)=7,"Sunday","Working"))) -> Working | J10: =IF(E10="","",IF(OR(WEEKDAY(E10,2)=7,COUNTIF($A$6:$A$55,E10)>0),"No","Yes")) -> Yes
A11: 46333 | E11: =IF(E10="","",IF(E10<DATE($B$2+1,1,1)-1,E10+1,"")) -> 46028 | F11: =IF(E11="","",TEXT(E11,"mmm")) -> Jan | G11: =IF(E11="","",WEEKNUM(E11,2)) -> 2 | H11: =IF(E11="","",TEXT(E11,"ddd")) -> Tue | I11: =IF(E11="","",IF(COUNTIF($A$6:$A$55,E11)>0,"Holiday",IF(WEEKDAY(E11,2)=7,"Sunday","Working"))) -> Working | J11: =IF(E11="","",IF(OR(WEEKDAY(E11,2)=7,COUNTIF($A$6:$A$55,E11)>0),"No","Yes")) -> Yes
A12: 46342 | E12: =IF(E11="","",IF(E11<DATE($B$2+1,1,1)-1,E11+1,"")) -> 46029 | F12: =IF(E12="","",TEXT(E12,"mmm")) -> Jan | G12: =IF(E12="","",WEEKNUM(E12,2)) -> 2 | H12: =IF(E12="","",TEXT(E12,"ddd")) -> Wed | I12: =IF(E12="","",IF(COUNTIF($A$6:$A$55,E12)>0,"Holiday",IF(WEEKDAY(E12,2)=7,"Sunday","Working"))) -> Working | J12: =IF(E12="","",IF(OR(WEEKDAY(E12,2)=7,COUNTIF($A$6:$A$55,E12)>0),"No","Yes")) -> Yes
E13: =IF(E12="","",IF(E12<DATE($B$2+1,1,1)-1,E12+1,"")) -> 46030 | F13: =IF(E13="","",TEXT(E13,"mmm")) -> Jan | G13: =IF(E13="","",WEEKNUM(E13,2)) -> 2 | H13: =IF(E13="","",TEXT(E13,"ddd")) -> Thu | I13: =IF(E13="","",IF(COUNTIF($A$6:$A$55,E13)>0,"Holiday",IF(WEEKDAY(E13,2)=7,"Sunday","Working"))) -> Working | J13: =IF(E13="","",IF(OR(WEEKDAY(E13,2)=7,COUNTIF($A$6:$A$55,E13)>0),"No","Yes")) -> Yes
E14: =IF(E13="","",IF(E13<DATE($B$2+1,1,1)-1,E13+1,"")) -> 46031 | F14: =IF(E14="","",TEXT(E14,"mmm")) -> Jan | G14: =IF(E14="","",WEEKNUM(E14,2)) -> 2 | H14: =IF(E14="","",TEXT(E14,"ddd")) -> Fri | I14: =IF(E14="","",IF(COUNTIF($A$6:$A$55,E14)>0,"Holiday",IF(WEEKDAY(E14,2)=7,"Sunday","Working"))) -> Working | J14: =IF(E14="","",IF(OR(WEEKDAY(E14,2)=7,COUNTIF($A$6:$A$55,E14)>0),"No","Yes")) -> Yes
E15: =IF(E14="","",IF(E14<DATE($B$2+1,1,1)-1,E14+1,"")) -> 46032 | F15: =IF(E15="","",TEXT(E15,"mmm")) -> Jan | G15: =IF(E15="","",WEEKNUM(E15,2)) -> 2 | H15: =IF(E15="","",TEXT(E15,"ddd")) -> Sat | I15: =IF(E15="","",IF(COUNTIF($A$6:$A$55,E15)>0,"Holiday",IF(WEEKDAY(E15,2)=7,"Sunday","Working"))) -> Working | J15: =IF(E15="","",IF(OR(WEEKDAY(E15,2)=7,COUNTIF($A$6:$A$55,E15)>0),"No","Yes")) -> Yes
E16: =IF(E15="","",IF(E15<DATE($B$2+1,1,1)-1,E15+1,"")) -> 46033 | F16: =IF(E16="","",TEXT(E16,"mmm")) -> Jan | G16: =IF(E16="","",WEEKNUM(E16,2)) -> 2 | H16: =IF(E16="","",TEXT(E16,"ddd")) -> Sun | I16: =IF(E16="","",IF(COUNTIF($A$6:$A$55,E16)>0,"Holiday",IF(WEEKDAY(E16,2)=7,"Sunday","Working"))) -> Sunday | J16: =IF(E16="","",IF(OR(WEEKDAY(E16,2)=7,COUNTIF($A$6:$A$55,E16)>0),"No","Yes")) -> No
E17: =IF(E16="","",IF(E16<DATE($B$2+1,1,1)-1,E16+1,"")) -> 46034 | F17: =IF(E17="","",TEXT(E17,"mmm")) -> Jan | G17: =IF(E17="","",WEEKNUM(E17,2)) -> 3 | H17: =IF(E17="","",TEXT(E17,"ddd")) -> Mon | I17: =IF(E17="","",IF(COUNTIF($A$6:$A$55,E17)>0,"Holiday",IF(WEEKDAY(E17,2)=7,"Sunday","Working"))) -> Working | J17: =IF(E17="","",IF(OR(WEEKDAY(E17,2)=7,COUNTIF($A$6:$A$55,E17)>0),"No","Yes")) -> Yes
E18: =IF(E17="","",IF(E17<DATE($B$2+1,1,1)-1,E17+1,"")) -> 46035 | F18: =IF(E18="","",TEXT(E18,"mmm")) -> Jan | G18: =IF(E18="","",WEEKNUM(E18,2)) -> 3 | H18: =IF(E18="","",TEXT(E18,"ddd")) -> Tue | I18: =IF(E18="","",IF(COUNTIF($A$6:$A$55,E18)>0,"Holiday",IF(WEEKDAY(E18,2)=7,"Sunday","Working"))) -> Working | J18: =IF(E18="","",IF(OR(WEEKDAY(E18,2)=7,COUNTIF($A$6:$A$55,E18)>0),"No","Yes")) -> Yes
E19: =IF(E18="","",IF(E18<DATE($B$2+1,1,1)-1,E18+1,"")) -> 46036 | F19: =IF(E19="","",TEXT(E19,"mmm")) -> Jan | G19: =IF(E19="","",WEEKNUM(E19,2)) -> 3 | H19: =IF(E19="","",TEXT(E19,"ddd")) -> Wed | I19: =IF(E19="","",IF(COUNTIF($A$6:$A$55,E19)>0,"Holiday",IF(WEEKDAY(E19,2)=7,"Sunday","Working"))) -> Working | J19: =IF(E19="","",IF(OR(WEEKDAY(E19,2)=7,COUNTIF($A$6:$A$55,E19)>0),"No","Yes")) -> Yes
E20: =IF(E19="","",IF(E19<DATE($B$2+1,1,1)-1,E19+1,"")) -> 46037 | F20: =IF(E20="","",TEXT(E20,"mmm")) -> Jan | G20: =IF(E20="","",WEEKNUM(E20,2)) -> 3 | H20: =IF(E20="","",TEXT(E20,"ddd")) -> Thu | I20: =IF(E20="","",IF(COUNTIF($A$6:$A$55,E20)>0,"Holiday",IF(WEEKDAY(E20,2)=7,"Sunday","Working"))) -> Working | J20: =IF(E20="","",IF(OR(WEEKDAY(E20,2)=7,COUNTIF($A$6:$A$55,E20)>0),"No","Yes")) -> Yes | Q20: 46264
E21: =IF(E20="","",IF(E20<DATE($B$2+1,1,1)-1,E20+1,"")) -> 46038 | F21: =IF(E21="","",TEXT(E21,"mmm")) -> Jan | G21: =IF(E21="","",WEEKNUM(E21,2)) -> 3 | H21: =IF(E21="","",TEXT(E21,"ddd")) -> Fri | I21: =IF(E21="","",IF(COUNTIF($A$6:$A$55,E21)>0,"Holiday",IF(WEEKDAY(E21,2)=7,"Sunday","Working"))) -> Working | J21: =IF(E21="","",IF(OR(WEEKDAY(E21,2)=7,COUNTIF($A$6:$A$55,E21)>0),"No","Yes")) -> Yes | Q21: 46285
E22: =IF(E21="","",IF(E21<DATE($B$2+1,1,1)-1,E21+1,"")) -> 46039 | F22: =IF(E22="","",TEXT(E22,"mmm")) -> Jan | G22: =IF(E22="","",WEEKNUM(E22,2)) -> 3 | H22: =IF(E22="","",TEXT(E22,"ddd")) -> Sat | I22: =IF(E22="","",IF(COUNTIF($A$6:$A$55,E22)>0,"Holiday",IF(WEEKDAY(E22,2)=7,"Sunday","Working"))) -> Working | J22: =IF(E22="","",IF(OR(WEEKDAY(E22,2)=7,COUNTIF($A$6:$A$55,E22)>0),"No","Yes")) -> Yes | Q22: 46313
E23: =IF(E22="","",IF(E22<DATE($B$2+1,1,1)-1,E22+1,"")) -> 46040 | F23: =IF(E23="","",TEXT(E23,"mmm")) -> Jan | G23: =IF(E23="","",WEEKNUM(E23,2)) -> 3 | H23: =IF(E23="","",TEXT(E23,"ddd")) -> Sun | I23: =IF(E23="","",IF(COUNTIF($A$6:$A$55,E23)>0,"Holiday",IF(WEEKDAY(E23,2)=7,"Sunday","Working"))) -> Sunday | J23: =IF(E23="","",IF(OR(WEEKDAY(E23,2)=7,COUNTIF($A$6:$A$55,E23)>0),"No","Yes")) -> No
E24: =IF(E23="","",IF(E23<DATE($B$2+1,1,1)-1,E23+1,"")) -> 46041 | F24: =IF(E24="","",TEXT(E24,"mmm")) -> Jan | G24: =IF(E24="","",WEEKNUM(E24,2)) -> 4 | H24: =IF(E24="","",TEXT(E24,"ddd")) -> Mon | I24: =IF(E24="","",IF(COUNTIF($A$6:$A$55,E24)>0,"Holiday",IF(WEEKDAY(E24,2)=7,"Sunday","Working"))) -> Working | J24: =IF(E24="","",IF(OR(WEEKDAY(E24,2)=7,COUNTIF($A$6:$A$55,E24)>0),"No","Yes")) -> Yes
E25: =IF(E24="","",IF(E24<DATE($B$2+1,1,1)-1,E24+1,"")) -> 46042 | F25: =IF(E25="","",TEXT(E25,"mmm")) -> Jan | G25: =IF(E25="","",WEEKNUM(E25,2)) -> 4 | H25: =IF(E25="","",TEXT(E25,"ddd")) -> Tue | I25: =IF(E25="","",IF(COUNTIF($A$6:$A$55,E25)>0,"Holiday",IF(WEEKDAY(E25,2)=7,"Sunday","Working"))) -> Working | J25: =IF(E25="","",IF(OR(WEEKDAY(E25,2)=7,COUNTIF($A$6:$A$55,E25)>0),"No","Yes")) -> Yes
E26: =IF(E25="","",IF(E25<DATE($B$2+1,1,1)-1,E25+1,"")) -> 46043 | F26: =IF(E26="","",TEXT(E26,"mmm")) -> Jan | G26: =IF(E26="","",WEEKNUM(E26,2)) -> 4 | H26: =IF(E26="","",TEXT(E26,"ddd")) -> Wed | I26: =IF(E26="","",IF(COUNTIF($A$6:$A$55,E26)>0,"Holiday",IF(WEEKDAY(E26,2)=7,"Sunday","Working"))) -> Working | J26: =IF(E26="","",IF(OR(WEEKDAY(E26,2)=7,COUNTIF($A$6:$A$55,E26)>0),"No","Yes")) -> Yes
E27: =IF(E26="","",IF(E26<DATE($B$2+1,1,1)-1,E26+1,"")) -> 46044 | F27: =IF(E27="","",TEXT(E27,"mmm")) -> Jan | G27: =IF(E27="","",WEEKNUM(E27,2)) -> 4 | H27: =IF(E27="","",TEXT(E27,"ddd")) -> Thu | I27: =IF(E27="","",IF(COUNTIF($A$6:$A$55,E27)>0,"Holiday",IF(WEEKDAY(E27,2)=7,"Sunday","Working"))) -> Working | J27: =IF(E27="","",IF(OR(WEEKDAY(E27,2)=7,COUNTIF($A$6:$A$55,E27)>0),"No","Yes")) -> Yes
E28: =IF(E27="","",IF(E27<DATE($B$2+1,1,1)-1,E27+1,"")) -> 46045 | F28: =IF(E28="","",TEXT(E28,"mmm")) -> Jan | G28: =IF(E28="","",WEEKNUM(E28,2)) -> 4 | H28: =IF(E28="","",TEXT(E28,"ddd")) -> Fri | I28: =IF(E28="","",IF(COUNTIF($A$6:$A$55,E28)>0,"Holiday",IF(WEEKDAY(E28,2)=7,"Sunday","Working"))) -> Working | J28: =IF(E28="","",IF(OR(WEEKDAY(E28,2)=7,COUNTIF($A$6:$A$55,E28)>0),"No","Yes")) -> Yes
E29: =IF(E28="","",IF(E28<DATE($B$2+1,1,1)-1,E28+1,"")) -> 46046 | F29: =IF(E29="","",TEXT(E29,"mmm")) -> Jan | G29: =IF(E29="","",WEEKNUM(E29,2)) -> 4 | H29: =IF(E29="","",TEXT(E29,"ddd")) -> Sat | I29: =IF(E29="","",IF(COUNTIF($A$6:$A$55,E29)>0,"Holiday",IF(WEEKDAY(E29,2)=7,"Sunday","Working"))) -> Working | J29: =IF(E29="","",IF(OR(WEEKDAY(E29,2)=7,COUNTIF($A$6:$A$55,E29)>0),"No","Yes")) -> Yes
E30: =IF(E29="","",IF(E29<DATE($B$2+1,1,1)-1,E29+1,"")) -> 46047 | F30: =IF(E30="","",TEXT(E30,"mmm")) -> Jan | G30: =IF(E30="","",WEEKNUM(E30,2)) -> 4 | H30: =IF(E30="","",TEXT(E30,"ddd")) -> Sun | I30: =IF(E30="","",IF(COUNTIF($A$6:$A$55,E30)>0,"Holiday",IF(WEEKDAY(E30,2)=7,"Sunday","Working"))) -> Sunday | J30: =IF(E30="","",IF(OR(WEEKDAY(E30,2)=7,COUNTIF($A$6:$A$55,E30)>0),"No","Yes")) -> No
E31: =IF(E30="","",IF(E30<DATE($B$2+1,1,1)-1,E30+1,"")) -> 46048 | F31: =IF(E31="","",TEXT(E31,"mmm")) -> Jan | G31: =IF(E31="","",WEEKNUM(E31,2)) -> 5 | H31: =IF(E31="","",TEXT(E31,"ddd")) -> Mon | I31: =IF(E31="","",IF(COUNTIF($A$6:$A$55,E31)>0,"Holiday",IF(WEEKDAY(E31,2)=7,"Sunday","Working"))) -> Holiday | J31: =IF(E31="","",IF(OR(WEEKDAY(E31,2)=7,COUNTIF($A$6:$A$55,E31)>0),"No","Yes")) -> No
E32: =IF(E31="","",IF(E31<DATE($B$2+1,1,1)-1,E31+1,"")) -> 46049 | F32: =IF(E32="","",TEXT(E32,"mmm")) -> Jan | G32: =IF(E32="","",WEEKNUM(E32,2)) -> 5 | H32: =IF(E32="","",TEXT(E32,"ddd")) -> Tue | I32: =IF(E32="","",IF(COUNTIF($A$6:$A$55,E32)>0,"Holiday",IF(WEEKDAY(E32,2)=7,"Sunday","Working"))) -> Working | J32: =IF(E32="","",IF(OR(WEEKDAY(E32,2)=7,COUNTIF($A$6:$A$55,E32)>0),"No","Yes")) -> Yes
E33: =IF(E32="","",IF(E32<DATE($B$2+1,1,1)-1,E32+1,"")) -> 46050 | F33: =IF(E33="","",TEXT(E33,"mmm")) -> Jan | G33: =IF(E33="","",WEEKNUM(E33,2)) -> 5 | H33: =IF(E33="","",TEXT(E33,"ddd")) -> Wed | I33: =IF(E33="","",IF(COUNTIF($A$6:$A$55,E33)>0,"Holiday",IF(WEEKDAY(E33,2)=7,"Sunday","Working"))) -> Working | J33: =IF(E33="","",IF(OR(WEEKDAY(E33,2)=7,COUNTIF($A$6:$A$55,E33)>0),"No","Yes")) -> Yes
E34: =IF(E33="","",IF(E33<DATE($B$2+1,1,1)-1,E33+1,"")) -> 46051 | F34: =IF(E34="","",TEXT(E34,"mmm")) -> Jan | G34: =IF(E34="","",WEEKNUM(E34,2)) -> 5 | H34: =IF(E34="","",TEXT(E34,"ddd")) -> Thu | I34: =IF(E34="","",IF(COUNTIF($A$6:$A$55,E34)>0,"Holiday",IF(WEEKDAY(E34,2)=7,"Sunday","Working"))) -> Working | J34: =IF(E34="","",IF(OR(WEEKDAY(E34,2)=7,COUNTIF($A$6:$A$55,E34)>0),"No","Yes")) -> Yes
... E371: =IF(E370="","",IF(E370<DATE($B$2+1,1,1)-1,E370+1,"")) | F371: =IF(E371="","",TEXT(E371,"mmm")) | G371: =IF(E371="","",WEEKNUM(E371,2)) | H371: =IF(E371="","",TEXT(E371,"ddd")) | I371: =IF(E371="","",IF(COUNTIF($A$6:$A$55,E371)>0,"Holiday",IF(WEEKDAY(E371,2)=7,"Sunday","Working"))) | J371: =IF(E371="","",IF(OR(WEEKDAY(E371,2)=7,COUNTIF($A$6:$A$55,E371)>0),"No","Yes"))
